Workbook
Name TeamList: Teams!$B$3:$B$52

Sheet Setup
A1: ⚽ Boules Tournament Manager
A3: TOURNAMENT DETAILS
A4: Tournament Name | B4: My Tournament
A5: Description
A6: Number of Divisions | B6: 2
A7: Games per Match | B7: 3
A8: Points for a Win | B8: 2
A9: Points for a Draw | B9: 1
A10: Points for a Loss | B10: 0
A12: STAGES INCLUDED
A13: Initial Round | B13: Yes
A14: Quarter-Finals | B14: No
A15: Semi-Finals | B15: Yes
A16: Finals | B16: Yes
A18: HOW TO USE THIS SPREADSHEET
A19: 1. Setup tab | B19: Fill in your tournament details above (yellow cells).
A20: 2. Teams tab | B20: Add all teams with their division (A, B, C, D...) and captain details.
A21: 3. Generate Matches | B21: Use the macro button on the Matches tab to auto-generate the round-robin schedule.
A22: 4. Enter Scores | B22: On the Matches tab, enter scores as matches are played. Winner & Status auto-calculate.
A23: 5. Leaderboard | B23: View the Leaderboard tab for live standings. Select a Stage using the dropdown.
A24: 6. Macro Setup | B24: To enable the Generate Matches button: open Excel, press Alt+F11, insert a Module,
B25: paste the VBA code from the 'Macro Code' tab, then close the VBA editor.
B26: Save the file as .xlsm (macro-enabled) to preserve the button.

Sheet Teams
A1: TEAMS
A2: Division | B2: Team Name | C2: Captain Name | D2: Captain Phone | E2: Captain Email

Sheet Matches
A1: MATCHES
A2: Date | B2: Stage | C2: Division | D2: Team 1 | E2: Team 2 | F2: G1 T1 | G2: G1 T2 | H2: G2 T1 | I2: G2 T2 | J2: G3 T1 | K2: G3 T2 | L2: Total T1 | M2: Total T2 | N2: Winner | O2: Status
L3: =IF(AND(D3="",E3=""),"",IFERROR(IF(F3<>"",F3,0)+IF(H3<>"",H3,0)+IF(J3<>"",J3,0),"")) | M3: =IF(AND(D3="",E3=""),"",IFERROR(IF(G3<>"",G3,0)+IF(I3<>"",I3,0)+IF(K3<>"",K3,0),"")) | N3: =IF(OR(L3="",M3=""),"",IF(L3>M3,D3,IF(M3>L3,E3,"Draw"))) | O3: =IF(AND(D3="",E3=""),"",IF(AND(L3<>"",M3<>""),"Completed","Scheduled"))
L4: =IF(AND(D4="",E4=""),"",IFERROR(IF(F4<>"",F4,0)+IF(H4<>"",H4,0)+IF(J4<>"",J4,0),"")) | M4: =IF(AND(D4="",E4=""),"",IFERROR(IF(G4<>"",G4,0)+IF(I4<>"",I4,0)+IF(K4<>"",K4,0),"")) | N4: =IF(OR(L4="",M4=""),"",IF(L4>M4,D4,IF(M4>L4,E4,"Draw"))) | O4: =IF(AND(D4="",E4=""),"",IF(AND(L4<>"",M4<>""),"Completed","Scheduled"))
L5: =IF(AND(D5="",E5=""),"",IFERROR(IF(F5<>"",F5,0)+IF(H5<>"",H5,0)+IF(J5<>"",J5,0),"")) | M5: =IF(AND(D5="",E5=""),"",IFERROR(IF(G5<>"",G5,0)+IF(I5<>"",I5,0)+IF(K5<>"",K5,0),"")) | N5: =IF(OR(L5="",M5=""),"",IF(L5>M5,D5,IF(M5>L5,E5,"Draw"))) | O5: =IF(AND(D5="",E5=""),"",IF(AND(L5<>"",M5<>""),"Completed","Scheduled"))
L6: =IF(AND(D6="",E6=""),"",IFERROR(IF(F6<>"",F6,0)+IF(H6<>"",H6,0)+IF(J6<>"",J6,0),"")) | M6: =IF(AND(D6="",E6=""),"",IFERROR(IF(G6<>"",G6,0)+IF(I6<>"",I6,0)+IF(K6<>"",K6,0),"")) | N6: =IF(OR(L6="",M6=""),"",IF(L6>M6,D6,IF(M6>L6,E6,"Draw"))) | O6: =IF(AND(D6="",E6=""),"",IF(AND(L6<>"",M6<>""),"Completed","Scheduled"))
L7: =IF(AND(D7="",E7=""),"",IFERROR(IF(F7<>"",F7,0)+IF(H7<>"",H7,0)+IF(J7<>"",J7,0),"")) | M7: =IF(AND(D7="",E7=""),"",IFERROR(IF(G7<>"",G7,0)+IF(I7<>"",I7,0)+IF(K7<>"",K7,0),"")) | N7: =IF(OR(L7="",M7=""),"",IF(L7>M7,D7,IF(M7>L7,E7,"Draw"))) | O7: =IF(AND(D7="",E7=""),"",IF(AND(L7<>"",M7<>""),"Completed","Scheduled"))
L8: =IF(AND(D8="",E8=""),"",IFERROR(IF(F8<>"",F8,0)+IF(H8<>"",H8,0)+IF(J8<>"",J8,0),"")) | M8: =IF(AND(D8="",E8=""),"",IFERROR(IF(G8<>"",G8,0)+IF(I8<>"",I8,0)+IF(K8<>"",K8,0),"")) | N8: =IF(OR(L8="",M8=""),"",IF(L8>M8,D8,IF(M8>L8,E8,"Draw"))) | O8: =IF(AND(D8="",E8=""),"",IF(AND(L8<>"",M8<>""),"Completed","Scheduled"))
L9: =IF(AND(D9="",E9=""),"",IFERROR(IF(F9<>"",F9,0)+IF(H9<>"",H9,0)+IF(J9<>"",J9,0),"")) | M9: =IF(AND(D9="",E9=""),"",IFERROR(IF(G9<>"",G9,0)+IF(I9<>"",I9,0)+IF(K9<>"",K9,0),"")) | N9: =IF(OR(L9="",M9=""),"",IF(L9>M9,D9,IF(M9>L9,E9,"Draw"))) | O9: =IF(AND(D9="",E9=""),"",IF(AND(L9<>"",M9<>""),"Completed","Scheduled"))
L10: =IF(AND(D10="",E10=""),"",IFERROR(IF(F10<>"",F10,0)+IF(H10<>"",H10,0)+IF(J10<>"",J10,0),"")) | M10: =IF(AND(D10="",E10=""),"",IFERROR(IF(G10<>"",G10,0)+IF(I10<>"",I10,0)+IF(K10<>"",K10,0),"")) | N10: =IF(OR(L10="",M10=""),"",IF(L10>M10,D10,IF(M10>L10,E10,"Draw"))) | O10: =IF(AND(D10="",E10=""),"",IF(AND(L10<>"",M10<>""),"Completed","Scheduled"))
L11: =IF(AND(D11="",E11=""),"",IFERROR(IF(F11<>"",F11,0)+IF(H11<>"",H11,0)+IF(J11<>"",J11,0),"")) | M11: =IF(AND(D11="",E11=""),"",IFERROR(IF(G11<>"",G11,0)+IF(I11<>"",I11,0)+IF(K11<>"",K11,0),"")) | N11: =IF(OR(L11="",M11=""),"",IF(L11>M11,D11,IF(M11>L11,E11,"Draw"))) | O11: =IF(AND(D11="",E11=""),"",IF(AND(L11<>"",M11<>""),"Completed","Scheduled"))
L12: =IF(AND(D12="",E12=""),"",IFERROR(IF(F12<>"",F12,0)+IF(H12<>"",H12,0)+IF(J12<>"",J12,0),"")) | M12: =IF(AND(D12="",E12=""),"",IFERROR(IF(G12<>"",G12,0)+IF(I12<>"",I12,0)+IF(K12<>"",K12,0),"")) | N12: =IF(OR(L12="",M12=""),"",IF(L12>M12,D12,IF(M12>L12,E12,"Draw"))) | O12: =IF(AND(D12="",E12=""),"",IF(AND(L12<>"",M12<>""),"Completed","Scheduled"))
L13: =IF(AND(D13="",E13=""),"",IFERROR(IF(F13<>"",F13,0)+IF(H13<>"",H13,0)+IF(J13<>"",J13,0),"")) | M13: =IF(AND(D13="",E13=""),"",IFERROR(IF(G13<>"",G13,0)+IF(I13<>"",I13,0)+IF(K13<>"",K13,0),"")) | N13: =IF(OR(L13="",M13=""),"",IF(L13>M13,D13,IF(M13>L13,E13,"Draw"))) | O13: =IF(AND(D13="",E13=""),"",IF(AND(L13<>"",M13<>""),"Completed","Scheduled"))
L14: =IF(AND(D14="",E14=""),"",IFERROR(IF(F14<>"",F14,0)+IF(H14<>"",H14,0)+IF(J14<>"",J14,0),"")) | M14: =IF(AND(D14="",E14=""),"",IFERROR(IF(G14<>"",G14,0)+IF(I14<>"",I14,0)+IF(K14<>"",K14,0),"")) | N14: =IF(OR(L14="",M14=""),"",IF(L14>M14,D14,IF(M14>L14,E14,"Draw"))) | O14: =IF(AND(D14="",E14=""),"",IF(AND(L14<>"",M14<>""),"Completed","Scheduled"))
... L502: =IF(AND(D502="",E502=""),"",IFERROR(IF(F502<>"",F502,0)+IF(H502<>"",H502,0)+IF(J502<>"",J502,0),"")) | M502: =IF(AND(D502="",E502=""),"",IFERROR(IF(G502<>"",G502,0)+IF(I502<>"",I502,0)+IF(K502<>"",K502,0),"")) | N502: =IF(OR(L502="",M502=""),"",IF(L502>M502,D502,IF(M502>L502,E502,"Draw"))) | O502: =IF(AND(D502="",E502=""),"",IF(AND(L502<>"",M502<>""),"Completed","Scheduled"))

Sheet Leaderboard
A1: LEADERBOARD
A3: Stage: | B3: Initial | D3: ← Change stage to view different standings
A5: DIVISION A
A6: Pos | B6: Team | C6: Played | D6: Won | E6: Drawn | F6: Lost | G6: Points | H6: GF | I6: GA | J6: Diff
B7: =IFERROR(INDEX(Teams!$B$3:$B$52,SMALL(IF(Teams!$A$3:$A$52="A",ROW(Teams!$A$3:$A$52)-ROW(Teams!$A$3)+1),1)),"") | C7: =IFERROR(IF(B7="","",SUMPRODUCT((Matches!$B$3:$B$502=$B$3)*(Matches!$D$3:$D$502=B7)*(Matches!$O$3:$O$502="Completed"))+SUMPRODUCT((Matches!$B$3:$B$502=$B$3)*(Matches!$E$3:$E$502=B7)*(Matches!$O$3:$O$502="Completed"))),"—") | D7: =IFERROR(IF(B7="","",SUMPRODUCT((Matches!$B$3:$B$502=$B$3)*(Matches!$D$3:$D$502=B7)*(Matches!$N$3:$N$502=B7)*(Matches!$O$3:$O$502="Completed"))+SUMPRODUCT((Matches!$B$3:$B$502=$B$3)*(Matches!$E$3:$E$502=B7)*(Matches!$N$3:$N$502=B7)*(Matches!$O$3:$O$502="Completed"))),"—") | E7: =IFERROR(IF(B7="","",SUMPRODUCT((Matches!$B$3:$B$502=$B$3)*(Matches!$D$3:$D$502=B7)*(Matches!$N$3:$N$502="Draw")*(Matches!$O$3:$O$502="Completed"))+SUMPRODUCT((Matches!$B$3:$B$502=$B$3)*(Matches!$E$3:$E$502=B7)*(Matches!$N$3:$N$502="Draw")*(Matches!$O$3:$O$502="Completed"))),"—") | F7: =IFERROR(IF(B7="","",IF(ISNUMBER(C7),C7-D7-E7,"—")),"—") | G7: =IFERROR(IF(B7="","",IF(ISNUMBER(D7),D7*Setup!$B$8+E7*Setup!$B$9+F7*Setup!$B$10,"—")),"—") | H7: =IFERROR(IF(B7="","",SUMPRODUCT((Matches!$B$3:$B$502=$B$3)*(Matches!$D$3:$D$502=B7)*(Matches!$O$3:$O$502="Completed")*IF(ISNUMBER(Matches!$L$3:$L$502),Matches!$L$3:$L$502,0))+SUMPRODUCT((Matches!$B$3:$B$502=$B$3)*(Matches!$E$3:$E$502=B7)*(Matches!$O$3:$O$502="Completed")*IF(ISNUMBER(Matches!$M$3:$M$502),Matches!$M$3:$M$502,0))),"—") | I7: =IFERROR(IF(B7="","",SUMPRODUCT((Matches!$B$3:$B$502=$B$3)*(Matches!$D$3:$D$502=B7)*(Matches!$O$3:$O$502="Completed")*IF(ISNUMBER(Matches!$M$3:$M$502),Matches!$M$3:$M$502,0))+SUMPRODUCT((Matches!$B$3:$B$502=$B$3)*(Matches!$E$3:$E$502=B7)*(Matches!$O$3:$O$502="Completed")*IF(ISNUMBER(Matches!$L$3:$L$502),Matches!$L$3:$L$502,0))),"—") | J7: =IFERROR(IF(B7="","",IF(ISNUMBER(H7),H7-I7,"—")),"—")
B8: =IFERROR(INDEX(Teams!$B$3:$B$52,SMALL(IF(Teams!$A$3:$A$52="A",ROW(Teams!$A$3:$A$52)-ROW(Teams!$A$3)+1),2)),"") | C8: =IFERROR(IF(B8="","",SUMPRODUCT((Matches!$B$3:$B$502=$B$3)*(Matches!$D$3:$D$502=B8)*(Matches!$O$3:$O$502="Completed"))+SUMPRODUCT((Matches!$B$3:$B$502=$B$3)*(Matches!$E$3:$E$502=B8)*(Matches!$O$3:$O$502="Completed"))),"—") | D8: =IFERROR(IF(B8="","",SUMPRODUCT((Matches!$B$3:$B$502=$B$3)*(Matches!$D$3:$D$502=B8)*(Matches!$N$3:$N$502=B8)*(Matches!$O$3:$O$502="Completed"))+SUMPRODUCT((Matches!$B$3:$B$502=$B$3)*(Matches!$E$3:$E$502=B8)*(Matches!$N$3:$N$502=B8)*(Matches!$O$3:$O$502="Completed"))),"—") | E8: =IFERROR(IF(B8="","",SUMPRODUCT((Matches!$B$3:$B$502=$B$3)*(Matches!$D$3:$D$502=B8)*(Matches!$N$3:$N$502="Draw")*(Matches!$O$3:$O$502="Completed"))+SUMPRODUCT((Matches!$B$3:$B$502=$B$3)*(Matches!$E$3:$E$502=B8)*(Matches!$N$3:$N$502="Draw")*(Matches!$O$3:$O$502="Completed"))),"—") | F8: =IFERROR(IF(B8="","",IF(ISNUMBER(C8),C8-D8-E8,"—")),"—") | G8: =IFERROR(IF(B8="","",IF(ISNUMBER(D8),D8*Setup!$B$8+E8*Setup!$B$9+F8*Setup!$B$10,"—")),"—") | H8: =IFERROR(IF(B8="","",SUMPRODUCT((Matches!$B$3:$B$502=$B$3)*(Matches!$D$3:$D$502=B8)*(Matches!$O$3:$O$502="Completed")*IF(ISNUMBER(Matches!$L$3:$L$502),Matches!$L$3:$L$502,0))+SUMPRODUCT((Matches!$B$3:$B$502=$B$3)*(Matches!$E$3:$E$502=B8)*(Matches!$O$3:$O$502="Completed")*IF(ISNUMBER(Matches!$M$3:$M$502),Matches!$M$3:$M$502,0))),"—") | I8: =IFERROR(IF(B8="","",SUMPRODUCT((Matches!$B$3:$B$502=$B$3)*(Matches!$D$3:$D$502=B8)*(Matches!$O$3:$O$502="Completed")*IF(ISNUMBER(Matches!$M$3:$M$502),Matches!$M$3:$M$502,0))+SUMPRODUCT((Matches!$B$3:$B$502=$B$3)*(Matches!$E$3:$E$502=B8)*(Matches!$O$3:$O$502="Completed")*IF(ISNUMBER(Matches!$L$3:$L$502),Matches!$L$3:$L$502,0))),"—") | J8: =IFERROR(IF(B8="","",IF(ISNUMBER(H8),H8-I8,"—")),"—")
B9: =IFERROR(INDEX(Teams!$B$3:$B$52,SMALL(IF(Teams!$A$3:$A$52="A",ROW(Teams!$A$3:$A$52)-ROW(Teams!$A$3)+1),3)),"") | C9: =IFERROR(IF(B9="","",SUMPRODUCT((Matches!$B$3:$B$502=$B$3)*(Matches!$D$3:$D$502=B9)*(Matches!$O$3:$O$502="Completed"))+SUMPRODUCT((Matches!$B$3:$B$502=$B$3)*(Matches!$E$3:$E$502=B9)*(Matches!$O$3:$O$502="Completed"))),"—") | D9: =IFERROR(IF(B9="","",SUMPRODUCT((Matches!$B$3:$B$502=$B$3)*(Matches!$D$3:$D$502=B9)*(Matches!$N$3:$N$502=B9)*(Matches!$O$3:$O$502="Completed"))+SUMPRODUCT((Matches!$B$3:$B$502=$B$3)*(Matches!$E$3:$E$502=B9)*(Matches!$N$3:$N$502=B9)*(Matches!$O$3:$O$502="Completed"))),"—") | E9: =IFERROR(IF(B9="","",SUMPRODUCT((Matches!$B$3:$B$502=$B$3)*(Matches!$D$3:$D$502=B9)*(Matches!$N$3:$N$502="Draw")*(Matches!$O$3:$O$502="Completed"))+SUMPRODUCT((Matches!$B$3:$B$502=$B$3)*(Matches!$E$3:$E$502=B9)*(Matches!$N$3:$N$502="Draw")*(Matches!$O$3:$O$502="Completed"))),"—") | F9: =IFERROR(IF(B9="","",IF(ISNUMBER(C9),C9-D9-E9,"—")),"—") | G9: =IFERROR(IF(B9="","",IF(ISNUMBER(D9),D9*Setup!$B$8+E9*Setup!$B$9+F9*Setup!$B$10,"—")),"—") | H9: =IFERROR(IF(B9="","",SUMPRODUCT((Matches!$B$3:$B$502=$B$3)*(Matches!$D$3:$D$502=B9)*(Matches!$O$3:$O$502="Completed")*IF(ISNUMBER(Matches!$L$3:$L$502),Matches!$L$3:$L$502,0))+SUMPRODUCT((Matches!$B$3:$B$502=$B$3)*(Matches!$E$3:$E$502=B9)*(Matches!$O$3:$O$502="Completed")*IF(ISNUMBER(Matches!$M$3:$M$502),Matches!$M$3:$M$502,0))),"—") | I9: =IFERROR(IF(B9="","",SUMPRODUCT((Matches!$B$3:$B$502=$B$3)*(Matches!$D$3:$D$502=B9)*(Matches!$O$3:$O$502="Completed")*IF(ISNUMBER(Matches!$M$3:$M$502),Matches!$M$3:$M$502,0))+SUMPRODUCT((Matches!$B$3:$B$502=$B$3)*(Matches!$E$3:$E$502=B9)*(Matches!$O$3:$O$502="Completed")*IF(ISNUMBER(Matches!$L$3:$L$502),Matches!$L$3:$L$502,0))),"—") | J9: =IFERROR(IF(B9="","",IF(ISNUMBER(H9),H9-I9,"—")),"—")
B10: =IFERROR(INDEX(Teams!$B$3:$B$52,SMALL(IF(Teams!$A$3:$A$52="A",ROW(Teams!$A$3:$A$52)-ROW(Teams!$A$3)+1),4)),"") | C10: =IFERROR(IF(B10="","",SUMPRODUCT((Matches!$B$3:$B$502=$B$3)*(Matches!$D$3:$D$502=B10)*(Matches!$O$3:$O$502="Completed"))+SUMPRODUCT((Matches!$B$3:$B$502=$B$3)*(Matches!$E$3:$E$502=B10)*(Matches!$O$3:$O$502="Completed"))),"—") | D10: =IFERROR(IF(B10="","",SUMPRODUCT((Matches!$B$3:$B$502=$B$3)*(Matches!$D$3:$D$502=B10)*(Matches!$N$3:$N$502=B10)*(Matches!$O$3:$O$502="Completed"))+SUMPRODUCT((Matches!$B$3:$B$502=$B$3)*(Matches!$E$3:$E$502=B10)*(Matches!$N$3:$N$502=B10)*(Matches!$O$3:$O$502="Completed"))),"—") | E10: =IFERROR(IF(B10="","",SUMPRODUCT((Matches!$B$3:$B$502=$B$3)*(Matches!$D$3:$D$502=B10)*(Matches!$N$3:$N$502="Draw")*(Matches!$O$3:$O$502="Completed"))+SUMPRODUCT((Matches!$B$3:$B$502=$B$3)*(Matches!$E$3:$E$502=B10)*(Matches!$N$3:$N$502="Draw")*(Matches!$O$3:$O$502="Completed"))),"—") | F10: =IFERROR(IF(B10="","",IF(ISNUMBER(C10),C10-D10-E10,"—")),"—") | G10: =IFERROR(IF(B10="","",IF(ISNUMBER(D10),D10*Setup!$B$8+E10*Setup!$B$9+F10*Setup!$B$10,"—")),"—") | H10: =IFERROR(IF(B10="","",SUMPRODUCT((Matches!$B$3:$B$502=$B$3)*(Matches!$D$3:$D$502=B10)*(Matches!$O$3:$O$502="Completed")*IF(ISNUMBER(Matches!$L$3:$L$502),Matches!$L$3:$L$502,0))+SUMPRODUCT((Matches!$B$3:$B$502=$B$3)*(Matches!$E$3:$E$502=B10)*(Matches!$O$3:$O$502="Completed")*IF(ISNUMBER(Matches!$M$3:$M$502),Matches!$M$3:$M$502,0))),"—") | I10: =IFERROR(IF(B10="","",SUMPRODUCT((Matches!$B$3:$B$502=$B$3)*(Matches!$D$3:$D$502=B10)*(Matches!$O$3:$O$502="Completed")*IF(ISNUMBER(Matches!$M$3:$M$502),Matches!$M$3:$M$502,0))+SUMPRODUCT((Matches!$B$3:$B$502=$B$3)*(Matches!$E$3:$E$502=B10)*(Matches!$O$3:$O$502="Completed")*IF(ISNUMBER(Matches!$L$3:$L$502),Matches!$L$3:$L$502,0))),"—") | J10: =IFERROR(IF(B10="","",IF(ISNUMBER(H10),H10-I10,"—")),"—")
B11: =IFERROR(INDEX(Teams!$B$3:$B$52,SMALL(IF(Teams!$A$3:$A$52="A",ROW(Teams!$A$3:$A$52)-ROW(Teams!$A$3)+1),5)),"") | C11: =IFERROR(IF(B11="","",SUMPRODUCT((Matches!$B$3:$B$502=$B$3)*(Matches!$D$3:$D$502=B11)*(Matches!$O$3:$O$502="Completed"))+SUMPRODUCT((Matches!$B$3:$B$502=$B$3)*(Matches!$E$3:$E$502=B11)*(Matches!$O$3:$O$502="Completed"))),"—") | D11: =IFERROR(IF(B11="","",SUMPRODUCT((Matches!$B$3:$B$502=$B$3)*(Matches!$D$3:$D$502=B11)*(Matches!$N$3:$N$502=B11)*(Matches!$O$3:$O$502="Completed"))+SUMPRODUCT((Matches!$B$3:$B$502=$B$3)*(Matches!$E$3:$E$502=B11)*(Matches!$N$3:$N$502=B11)*(Matches!$O$3:$O$502="Completed"))),"—") | E11: =IFERROR(IF(B11="","",SUMPRODUCT((Matches!$B$3:$B$502=$B$3)*(Matches!$D$3:$D$502=B11)*(Matches!$N$3:$N$502="Draw")*(Matches!$O$3:$O$502="Completed"))+SUMPRODUCT((Matches!$B$3:$B$502=$B$3)*(Matches!$E$3:$E$502=B11)*(Matches!$N$3:$N$502="Draw")*(Matches!$O$3:$O$502="Completed"))),"—") | F11: =IFERROR(IF(B11="","",IF(ISNUMBER(C11),C11-D11-E11,"—")),"—") | G11: =IFERROR(IF(B11="","",IF(ISNUMBER(D11),D11*Setup!$B$8+E11*Setup!$B$9+F11*Setup!$B$10,"—")),"—") | H11: =IFERROR(IF(B11="","",SUMPRODUCT((Matches!$B$3:$B$502=$B$3)*(Matches!$D$3:$D$502=B11)*(Matches!$O$3:$O$502="Completed")*IF(ISNUMBER(Matches!$L$3:$L$502),Matches!$L$3:$L$502,0))+SUMPRODUCT((Matches!$B$3:$B$502=$B$3)*(Matches!$E$3:$E$502=B11)*(Matches!$O$3:$O$502="Completed")*IF(ISNUMBER(Matches!$M$3:$M$502),Matches!$M$3:$M$502,0))),"—") | I11: =IFERROR(IF(B11="","",SUMPRODUCT((Matches!$B$3:$B$502=$B$3)*(Matches!$D$3:$D$502=B11)*(Matches!$O$3:$O$502="Completed")*IF(ISNUMBER(Matches!$M$3:$M$502),Matches!$M$3:$M$502,0))+SUMPRODUCT((Matches!$B$3:$B$502=$B$3)*(Matches!$E$3:$E$502=B11)*(Matches!$O$3:$O$502="Completed")*IF(ISNUMBER(Matches!$L$3:$L$502),Matches!$L$3:$L$502,0))),"—") | J11: =IFERROR(IF(B11="","",IF(ISNUMBER(H11),H11-I11,"—")),"—")
B12: =IFERROR(INDEX(Teams!$B$3:$B$52,SMALL(IF(Teams!$A$3:$A$52="A",ROW(Teams!$A$3:$A$52)-ROW(Teams!$A$3)+1),6)),"") | C12: =IFERROR(IF(B12="","",SUMPRODUCT((Matches!$B$3:$B$502=$B$3)*(Matches!$D$3:$D$502=B12)*(Matches!$O$3:$O$502="Completed"))+SUMPRODUCT((Matches!$B$3:$B$502=$B$3)*(Matches!$E$3:$E$502=B12)*(Matches!$O$3:$O$502="Completed"))),"—") | D12: =IFERROR(IF(B12="","",SUMPRODUCT((Matches!$B$3:$B$502=$B$3)*(Matches!$D$3:$D$502=B12)*(Matches!$N$3:$N$502=B12)*(Matches!$O$3:$O$502="Completed"))+SUMPRODUCT((Matches!$B$3:$B$502=$B$3)*(Matches!$E$3:$E$502=B12)*(Matches!$N$3:$N$502=B12)*(Matches!$O$3:$O$502="Completed"))),"—") | E12: =IFERROR(IF(B12="","",SUMPRODUCT((Matches!$B$3:$B$502=$B$3)*(Matches!$D$3:$D$502=B12)*(Matches!$N$3:$N$502="Draw")*(Matches!$O$3:$O$502="Completed"))+SUMPRODUCT((Matches!$B$3:$B$502=$B$3)*(Matches!$E$3:$E$502=B12)*(Matches!$N$3:$N$502="Draw")*(Matches!$O$3:$O$502="Completed"))),"—") | F12: =IFERROR(IF(B12="","",IF(ISNUMBER(C12),C12-D12-E12,"—")),"—") | G12: =IFERROR(IF(B12="","",IF(ISNUMBER(D12),D12*Setup!$B$8+E12*Setup!$B$9+F12*Setup!$B$10,"—")),"—") | H12: =IFERROR(IF(B12="","",SUMPRODUCT((Matches!$B$3:$B$502=$B$3)*(Matches!$D$3:$D$502=B12)*(Matches!$O$3:$O$502="Completed")*IF(ISNUMBER(Matches!$L$3:$L$502),Matches!$L$3:$L$502,0))+SUMPRODUCT((Matches!$B$3:$B$502=$B$3)*(Matches!$E$3:$E$502=B12)*(Matches!$O$3:$O$502="Completed")*IF(ISNUMBER(Matches!$M$3:$M$502),Matches!$M$3:$M$502,0))),"—") | I12: =IFERROR(IF(B12="","",SUMPRODUCT((Matches!$B$3:$B$502=$B$3)*(Matches!$D$3:$D$502=B12)*(Matches!$O$3:$O$502="Completed")*IF(ISNUMBER(Matches!$M$3:$M$502),Matches!$M$3:$M$502,0))+SUMPRODUCT((Matches!$B$3:$B$502=$B$3)*(Matches!$E$3:$E$502=B12)*(Matches!$O$3:$O$502="Completed")*IF(ISNUMBER(Matches!$L$3:$L$502),Matches!$L$3:$L$502,0))),"—") | J12: =IFERROR(IF(B12="","",IF(ISNUMBER(H12),H12-I12,"—")),"—")
B13: =IFERROR(INDEX(Teams!$B$3:$B$52,SMALL(IF(Teams!$A$3:$A$52="A",ROW(Teams!$A$3:$A$52)-ROW(Teams!$A$3)+1),7)),"") | C13: =IFERROR(IF(B13="","",SUMPRODUCT((Matches!$B$3:$B$502=$B$3)*(Matches!$D$3:$D$502=B13)*(Matches!$O$3:$O$502="Completed"))+SUMPRODUCT((Matches!$B$3:$B$502=$B$3)*(Matches!$E$3:$E$502=B13)*(Matches!$O$3:$O$502="Completed"))),"—") | D13: =IFERROR(IF(B13="","",SUMPRODUCT((Matches!$B$3:$B$502=$B$3)*(Matches!$D$3:$D$502=B13)*(Matches!$N$3:$N$502=B13)*(Matches!$O$3:$O$502="Completed"))+SUMPRODUCT((Matches!$B$3:$B$502=$B$3)*(Matches!$E$3:$E$502=B13)*(Matches!$N$3:$N$502=B13)*(Matches!$O$3:$O$502="Completed"))),"—") | E13: =IFERROR(IF(B13="","",SUMPRODUCT((Matches!$B$3:$B$502=$B$3)*(Matches!$D$3:$D$502=B13)*(Matches!$N$3:$N$502="Draw")*(Matches!$O$3:$O$502="Completed"))+SUMPRODUCT((Matches!$B$3:$B$502=$B$3)*(Matches!$E$3:$E$502=B13)*(Matches!$N$3:$N$502="Draw")*(Matches!$O$3:$O$502="Completed"))),"—") | F13: =IFERROR(IF(B13="","",IF(ISNUMBER(C13),C13-D13-E13,"—")),"—") | G13: =IFERROR(IF(B13="","",IF(ISNUMBER(D13),D13*Setup!$B$8+E13*Setup!$B$9+F13*Setup!$B$10,"—")),"—") | H13: =IFERROR(IF(B13="","",SUMPRODUCT((Matches!$B$3:$B$502=$B$3)*(Matches!$D$3:$D$502=B13)*(Matches!$O$3:$O$502="Completed")*IF(ISNUMBER(Matches!$L$3:$L$502),Matches!$L$3:$L$502,0))+SUMPRODUCT((Matches!$B$3:$B$502=$B$3)*(Matches!$E$3:$E$502=B13)*(Matches!$O$3:$O$502="Completed")*IF(ISNUMBER(Matches!$M$3:$M$502),Matches!$M$3:$M$502,0))),"—") | I13: =IFERROR(IF(B13="","",SUMPRODUCT((Matches!$B$3:$B$502=$B$3)*(Matches!$D$3:$D$502=B13)*(Matches!$O$3:$O$502="Completed")*IF(ISNUMBER(Matches!$M$3:$M$502),Matches!$M$3:$M$502,0))+SUMPRODUCT((Matches!$B$3:$B$502=$B$3)*(Matches!$E$3:$E$502=B13)*(Matches!$O$3:$O$502="Completed")*IF(ISNUMBER(Matches!$L$3:$L$502),Matches!$L$3:$L$502,0))),"—") | J13: =IFERROR(IF(B13="","",IF(ISNUMBER(H13),H13-I13,"—")),"—")
B14: =IFERROR(INDEX(Teams!$B$3:$B$52,SMALL(IF(Teams!$A$3:$A$52="A",ROW(Teams!$A$3:$A$52)-ROW(Teams!$A$3)+1),8)),"") | C14: =IFERROR(IF(B14="","",SUMPRODUCT((Matches!$B$3:$B$502=$B$3)*(Matches!$D$3:$D$502=B14)*(Matches!$O$3:$O$502="Completed"))+SUMPRODUCT((Matches!$B$3:$B$502=$B$3)*(Matches!$E$3:$E$502=B14)*(Matches!$O$3:$O$502="Completed"))),"—") | D14: =IFERROR(IF(B14="","",SUMPRODUCT((Matches!$B$3:$B$502=$B$3)*(Matches!$D$3:$D$502=B14)*(Matches!$N$3:$N$502=B14)*(Matches!$O$3:$O$502="Completed"))+SUMPRODUCT((Matches!$B$3:$B$502=$B$3)*(Matches!$E$3:$E$502=B14)*(Matches!$N$3:$N$502=B14)*(Matches!$O$3:$O$502="Completed"))),"—") | E14: =IFERROR(IF(B14="","",SUMPRODUCT((Matches!$B$3:$B$502=$B$3)*(Matches!$D$3:$D$502=B14)*(Matches!$N$3:$N$502="Draw")*(Matches!$O$3:$O$502="Completed"))+SUMPRODUCT((Matches!$B$3:$B$502=$B$3)*(Matches!$E$3:$E$502=B14)*(Matches!$N$3:$N$502="Draw")*(Matches!$O$3:$O$502="Completed"))),"—") | F14: =IFERROR(IF(B14="","",IF(ISNUMBER(C14),C14-D14-E14,"—")),"—") | G14: =IFERROR(IF(B14="","",IF(ISNUMBER(D14),D14*Setup!$B$8+E14*Setup!$B$9+F14*Setup!$B$10,"—")),"—") | H14: =IFERROR(IF(B14="","",SUMPRODUCT((Matches!$B$3:$B$502=$B$3)*(Matches!$D$3:$D$502=B14)*(Matches!$O$3:$O$502="Completed")*IF(ISNUMBER(Matches!$L$3:$L$502),Matches!$L$3:$L$502,0))+SUMPRODUCT((Matches!$B$3:$B$502=$B$3)*(Matches!$E$3:$E$502=B14)*(Matches!$O$3:$O$502="Completed")*IF(ISNUMBER(Matches!$M$3:$M$502),Matches!$M$3:$M$502,0))),"—") | I14: =IFERROR(IF(B14="","",SUMPRODUCT((Matches!$B$3:$B$502=$B$3)*(Matches!$D$3:$D$502=B14)*(Matches!$O$3:$O$502="Completed")*IF(ISNUMBER(Matches!$M$3:$M$502),Matches!$M$3:$M$502,0))+SUMPRODUCT((Matches!$B$3:$B$502=$B$3)*(Matches!$E$3:$E$502=B14)*(Matches!$O$3:$O$502="Completed")*IF(ISNUMBER(Matches!$L$3:$L$502),Matches!$L$3:$L$502,0))),"—") | J14: =IFERROR(IF(B14="","",IF(ISNUMBER(H14),H14-I14,"—")),"—")
B15: =IFERROR(INDEX(Teams!$B$3:$B$52,SMALL(IF(Teams!$A$3:$A$52="A",ROW(Teams!$A$3:$A$52)-ROW(Teams!$A$3)+1),9)),"") | C15: =IFERROR(IF(B15="","",SUMPRODUCT((Matches!$B$3:$B$502=$B$3)*(Matches!$D$3:$D$502=B15)*(Matches!$O$3:$O$502="Completed"))+SUMPRODUCT((Matches!$B$3:$B$502=$B$3)*(Matches!$E$3:$E$502=B15)*(Matches!$O$3:$O$502="Completed"))),"—") | D15: =IFERROR(IF(B15="","",SUMPRODUCT((Matches!$B$3:$B$502=$B$3)*(Matches!$D$3:$D$502=B15)*(Matches!$N$3:$N$502=B15)*(Matches!$O$3:$O$502="Completed"))+SUMPRODUCT((Matches!$B$3:$B$502=$B$3)*(Matches!$E$3:$E$502=B15)*(Matches!$N$3:$N$502=B15)*(Matches!$O$3:$O$502="Completed"))),"—") | E15: =IFERROR(IF(B15="","",SUMPRODUCT((Matches!$B$3:$B$502=$B$3)*(Matches!$D$3:$D$502=B15)*(Matches!$N$3:$N$502="Draw")*(Matches!$O$3:$O$502="Completed"))+SUMPRODUCT((Matches!$B$3:$B$502=$B$3)*(Matches!$E$3:$E$502=B15)*(Matches!$N$3:$N$502="Draw")*(Matches!$O$3:$O$502="Completed"))),"—") | F15: =IFERROR(IF(B15="","",IF(ISNUMBER(C15),C15-D15-E15,"—")),"—") | G15: =IFERROR(IF(B15="","",IF(ISNUMBER(D15),D15*Setup!$B$8+E15*Setup!$B$9+F15*Setup!$B$10,"—")),"—") | H15: =IFERROR(IF(B15="","",SUMPRODUCT((Matches!$B$3:$B$502=$B$3)*(Matches!$D$3:$D$502=B15)*(Matches!$O$3:$O$502="Completed")*IF(ISNUMBER(Matches!$L$3:$L$502),Matches!$L$3:$L$502,0))+SUMPRODUCT((Matches!$B$3:$B$502=$B$3)*(Matches!$E$3:$E$502=B15)*(Matches!$O$3:$O$502="Completed")*IF(ISNUMBER(Matches!$M$3:$M$502),Matches!$M$3:$M$502,0))),"—") | I15: =IFERROR(IF(B15="","",SUMPRODUCT((Matches!$B$3:$B$502=$B$3)*(Matches!$D$3:$D$502=B15)*(Matches!$O$3:$O$502="Completed")*IF(ISNUMBER(Matches!$M$3:$M$502),Matches!$M$3:$M$502,0))+SUMPRODUCT((Matches!$B$3:$B$502=$B$3)*(Matches!$E$3:$E$502=B15)*(Matches!$O$3:$O$502="Completed")*IF(ISNUMBER(Matches!$L$3:$L$502),Matches!$L$3:$L$502,0))),"—") | J15: =IFERROR(IF(B15="","",IF(ISNUMBER(H15),H15-I15,"—")),"—")
B16: =IFERROR(INDEX(Teams!$B$3:$B$52,SMALL(IF(Teams!$A$3:$A$52="A",ROW(Teams!$A$3:$A$52)-ROW(Teams!$A$3)+1),10)),"") | C16: =IFERROR(IF(B16="","",SUMPRODUCT((Matches!$B$3:$B$502=$B$3)*(Matches!$D$3:$D$502=B16)*(Matches!$O$3:$O$502="Completed"))+SUMPRODUCT((Matches!$B$3:$B$502=$B$3)*(Matches!$E$3:$E$502=B16)*(Matches!$O$3:$O$502="Completed"))),"—") | D16: =IFERROR(IF(B16="","",SUMPRODUCT((Matches!$B$3:$B$502=$B$3)*(Matches!$D$3:$D$502=B16)*(Matches!$N$3:$N$502=B16)*(Matches!$O$3:$O$502="Completed"))+SUMPRODUCT((Matches!$B$3:$B$502=$B$3)*(Matches!$E$3:$E$502=B16)*(Matches!$N$3:$N$502=B16)*(Matches!$O$3:$O$502="Completed"))),"—") | E16: =IFERROR(IF(B16="","",SUMPRODUCT((Matches!$B$3:$B$502=$B$3)*(Matches!$D$3:$D$502=B16)*(Matches!$N$3:$N$502="Draw")*(Matches!$O$3:$O$502="Completed"))+SUMPRODUCT((Matches!$B$3:$B$502=$B$3)*(Matches!$E$3:$E$502=B16)*(Matches!$N$3:$N$502="Draw")*(Matches!$O$3:$O$502="Completed"))),"—") | F16: =IFERROR(IF(B16="","",IF(ISNUMBER(C16),C16-D16-E16,"—")),"—") | G16: =IFERROR(IF(B16="","",IF(ISNUMBER(D16),D16*Setup!$B$8+E16*Setup!$B$9+F16*Setup!$B$10,"—")),"—") | H16: =IFERROR(IF(B16="","",SUMPRODUCT((Matches!$B$3:$B$502=$B$3)*(Matches!$D$3:$D$502=B16)*(Matches!$O$3:$O$502="Completed")*IF(ISNUMBER(Matches!$L$3:$L$502),Matches!$L$3:$L$502,0))+SUMPRODUCT((Matches!$B$3:$B$502=$B$3)*(Matches!$E$3:$E$502=B16)*(Matches!$O$3:$O$502="Completed")*IF(ISNUMBER(Matches!$M$3:$M$502),Matches!$M$3:$M$502,0))),"—") | I16: =IFERROR(IF(B16="","",SUMPRODUCT((Matches!$B$3:$B$502=$B$3)*(Matches!$D$3:$D$502=B16)*(Matches!$O$3:$O$502="Completed")*IF(ISNUMBER(Matches!$M$3:$M$502),Matches!$M$3:$M$502,0))+SUMPRODUCT((Matches!$B$3:$B$502=$B$3)*(Matches!$E$3:$E$502=B16)*(Matches!$O$3:$O$502="Completed")*IF(ISNUMBER(Matches!$L$3:$L$502),Matches!$L$3:$L$502,0))),"—") | J16: =IFERROR(IF(B16="","",IF(ISNUMBER(H16),H16-I16,"—")),"—")
B17: =IFERROR(INDEX(Teams!$B$3:$B$52,SMALL(IF(Teams!$A$3:$A$52="A",ROW(Teams!$A$3:$A$52)-ROW(Teams!$A$3)+1),11)),"") | C17: =IFERROR(IF(B17="","",SUMPRODUCT((Matches!$B$3:$B$502=$B$3)*(Matches!$D$3:$D$502=B17)*(Matches!$O$3:$O$502="Completed"))+SUMPRODUCT((Matches!$B$3:$B$502=$B$3)*(Matches!$E$3:$E$502=B17)*(Matches!$O$3:$O$502="Completed"))),"—") | D17: =IFERROR(IF(B17="","",SUMPRODUCT((Matches!$B$3:$B$502=$B$3)*(Matches!$D$3:$D$502=B17)*(Matches!$N$3:$N$502=B17)*(Matches!$O$3:$O$502="Completed"))+SUMPRODUCT((Matches!$B$3:$B$502=$B$3)*(Matches!$E$3:$E$502=B17)*(Matches!$N$3:$N$502=B17)*(Matches!$O$3:$O$502="Completed"))),"—") | E17: =IFERROR(IF(B17="","",SUMPRODUCT((Matches!$B$3:$B$502=$B$3)*(Matches!$D$3:$D$502=B17)*(Matches!$N$3:$N$502="Draw")*(Matches!$O$3:$O$502="Completed"))+SUMPRODUCT((Matches!$B$3:$B$502=$B$3)*(Matches!$E$3:$E$502=B17)*(Matches!$N$3:$N$502="Draw")*(Matches!$O$3:$O$502="Completed"))),"—") | F17: =IFERROR(IF(B17="","",IF(ISNUMBER(C17),C17-D17-E17,"—")),"—") | G17: =IFERROR(IF(B17="","",IF(ISNUMBER(D17),D17*Setup!$B$8+E17*Setup!$B$9+F17*Setup!$B$10,"—")),"—") | H17: =IFERROR(IF(B17="","",SUMPRODUCT((Matches!$B$3:$B$502=$B$3)*(Matches!$D$3:$D$502=B17)*(Matches!$O$3:$O$502="Completed")*IF(ISNUMBER(Matches!$L$3:$L$502),Matches!$L$3:$L$502,0))+SUMPRODUCT((Matches!$B$3:$B$502=$B$3)*(Matches!$E$3:$E$502=B17)*(Matches!$O$3:$O$502="Completed")*IF(ISNUMBER(Matches!$M$3:$M$502),Matches!$M$3:$M$502,0))),"—") | I17: =IFERROR(IF(B17="","",SUMPRODUCT((Matches!$B$3:$B$502=$B$3)*(Matches!$D$3:$D$502=B17)*(Matches!$O$3:$O$502="Completed")*IF(ISNUMBER(Matches!$M$3:$M$502),Matches!$M$3:$M$502,0))+SUMPRODUCT((Matches!$B$3:$B$502=$B$3)*(Matches!$E$3:$E$502=B17)*(Matches!$O$3:$O$502="Completed")*IF(ISNUMBER(Matches!$L$3:$L$502),Matches!$L$3:$L$502,0))),"—") | J17: =IFERROR(IF(B17="","",IF(ISNUMBER(H17),H17-I17,"—")),"—")
B18: =IFERROR(INDEX(Teams!$B$3:$B$52,SMALL(IF(Teams!$A$3:$A$52="A",ROW(Teams!$A$3:$A$52)-ROW(Teams!$A$3)+1),12)),"") | C18: =IFERROR(IF(B18="","",SUMPRODUCT((Matches!$B$3:$B$502=$B$3)*(Matches!$D$3:$D$502=B18)*(Matches!$O$3:$O$502="Completed"))+SUMPRODUCT((Matches!$B$3:$B$502=$B$3)*(Matches!$E$3:$E$502=B18)*(Matches!$O$3:$O$502="Completed"))),"—") | D18: =IFERROR(IF(B18="","",SUMPRODUCT((Matches!$B$3:$B$502=$B$3)*(Matches!$D$3:$D$502=B18)*(Matches!$N$3:$N$502=B18)*(Matches!$O$3:$O$502="Completed"))+SUMPRODUCT((Matches!$B$3:$B$502=$B$3)*(Matches!$E$3:$E$502=B18)*(Matches!$N$3:$N$502=B18)*(Matches!$O$3:$O$502="Completed"))),"—") | E18: =IFERROR(IF(B18="","",SUMPRODUCT((Matches!$B$3:$B$502=$B$3)*(Matches!$D$3:$D$502=B18)*(Matches!$N$3:$N$502="Draw")*(Matches!$O$3:$O$502="Completed"))+SUMPRODUCT((Matches!$B$3:$B$502=$B$3)*(Matches!$E$3:$E$502=B18)*(Matches!$N$3:$N$502="Draw")*(Matches!$O$3:$O$502="Completed"))),"—") | F18: =IFERROR(IF(B18="","",IF(ISNUMBER(C18),C18-D18-E18,"—")),"—") | G18: =IFERROR(IF(B18="","",IF(ISNUMBER(D18),D18*Setup!$B$8+E18*Setup!$B$9+F18*Setup!$B$10,"—")),"—") | H18: =IFERROR(IF(B18="","",SUMPRODUCT((Matches!$B$3:$B$502=$B$3)*(Matches!$D$3:$D$502=B18)*(Matches!$O$3:$O$502="Completed")*IF(ISNUMBER(Matches!$L$3:$L$502),Matches!$L$3:$L$502,0))+SUMPRODUCT((Matches!$B$3:$B$502=$B$3)*(Matches!$E$3:$E$502=B18)*(Matches!$O$3:$O$502="Completed")*IF(ISNUMBER(Matches!$M$3:$M$502),Matches!$M$3:$M$502,0))),"—") | I18: =IFERROR(IF(B18="","",SUMPRODUCT((Matches!$B$3:$B$502=$B$3)*(Matches!$D$3:$D$502=B18)*(Matches!$O$3:$O$502="Completed")*IF(ISNUMBER(Matches!$M$3:$M$502),Matches!$M$3:$M$502,0))+SUMPRODUCT((Matches!$B$3:$B$502=$B$3)*(Matches!$E$3:$E$502=B18)*(Matches!$O$3:$O$502="Completed")*IF(ISNUMBER(Matches!$L$3:$L$502),Matches!$L$3:$L$502,0))),"—") | J18: =IFERROR(IF(B18="","",IF(ISNUMBER(H18),H18-I18,"—")),"—")
B19: =IFERROR(INDEX(Teams!$B$3:$B$52,SMALL(IF(Teams!$A$3:$A$52="A",ROW(Teams!$A$3:$A$52)-ROW(Teams!$A$3)+1),13)),"") | C19: =IFERROR(IF(B19="","",SUMPRODUCT((Matches!$B$3:$B$502=$B$3)*(Matches!$D$3:$D$502=B19)*(Matches!$O$3:$O$502="Completed"))+SUMPRODUCT((Matches!$B$3:$B$502=$B$3)*(Matches!$E$3:$E$502=B19)*(Matches!$O$3:$O$502="Completed"))),"—") | D19: =IFERROR(IF(B19="","",SUMPRODUCT((Matches!$B$3:$B$502=$B$3)*(Matches!$D$3:$D$502=B19)*(Matches!$N$3:$N$502=B19)*(Matches!$O$3:$O$502="Completed"))+SUMPRODUCT((Matches!$B$3:$B$502=$B$3)*(Matches!$E$3:$E$502=B19)*(Matches!$N$3:$N$502=B19)*(Matches!$O$3:$O$502="Completed"))),"—") | E19: =IFERROR(IF(B19="","",SUMPRODUCT((Matches!$B$3:$B$502=$B$3)*(Matches!$D$3:$D$502=B19)*(Matches!$N$3:$N$502="Draw")*(Matches!$O$3:$O$502="Completed"))+SUMPRODUCT((Matches!$B$3:$B$502=$B$3)*(Matches!$E$3:$E$502=B19)*(Matches!$N$3:$N$502="Draw")*(Matches!$O$3:$O$502="Completed"))),"—") | F19: =IFERROR(IF(B19="","",IF(ISNUMBER(C19),C19-D19-E19,"—")),"—") | G19: =IFERROR(IF(B19="","",IF(ISNUMBER(D19),D19*Setup!$B$8+E19*Setup!$B$9+F19*Setup!$B$10,"—")),"—") | H19: =IFERROR(IF(B19="","",SUMPRODUCT((Matches!$B$3:$B$502=$B$3)*(Matches!$D$3:$D$502=B19)*(Matches!$O$3:$O$502="Completed")*IF(ISNUMBER(Matches!$L$3:$L$502),Matches!$L$3:$L$502,0))+SUMPRODUCT((Matches!$B$3:$B$502=$B$3)*(Matches!$E$3:$E$502=B19)*(Matches!$O$3:$O$502="Completed")*IF(ISNUMBER(Matches!$M$3:$M$502),Matches!$M$3:$M$502,0))),"—") | I19: =IFERROR(IF(B19="","",SUMPRODUCT((Matches!$B$3:$B$502=$B$3)*(Matches!$D$3:$D$502=B19)*(Matches!$O$3:$O$502="Completed")*IF(ISNUMBER(Matches!$M$3:$M$502),Matches!$M$3:$M$502,0))+SUMPRODUCT((Matches!$B$3:$B$502=$B$3)*(Matches!$E$3:$E$502=B19)*(Matches!$O$3:$O$502="Completed")*IF(ISNUMBER(Matches!$L$3:$L$502),Matches!$L$3:$L$502,0))),"—") | J19: =IFERROR(IF(B19="","",IF(ISNUMBER(H19),H19-I19,"—")),"—")
B20: =IFERROR(INDEX(Teams!$B$3:$B$52,SMALL(IF(Teams!$A$3:$A$52="A",ROW(Teams!$A$3:$A$52)-ROW(Teams!$A$3)+1),14)),"") | C20: =IFERROR(IF(B20="","",SUMPRODUCT((Matches!$B$3:$B$502=$B$3)*(Matches!$D$3:$D$502=B20)*(Matches!$O$3:$O$502="Completed"))+SUMPRODUCT((Matches!$B$3:$B$502=$B$3)*(Matches!$E$3:$E$502=B20)*(Matches!$O$3:$O$502="Completed"))),"—") | D20: =IFERROR(IF(B20="","",SUMPRODUCT((Matches!$B$3:$B$502=$B$3)*(Matches!$D$3:$D$502=B20)*(Matches!$N$3:$N$502=B20)*(Matches!$O$3:$O$502="Completed"))+SUMPRODUCT((Matches!$B$3:$B$502=$B$3)*(Matches!$E$3:$E$502=B20)*(Matches!$N$3:$N$502=B20)*(Matches!$O$3:$O$502="Completed"))),"—") | E20: =IFERROR(IF(B20="","",SUMPRODUCT((Matches!$B$3:$B$502=$B$3)*(Matches!$D$3:$D$502=B20)*(Matches!$N$3:$N$502="Draw")*(Matches!$O$3:$O$502="Completed"))+SUMPRODUCT((Matches!$B$3:$B$502=$B$3)*(Matches!$E$3:$E$502=B20)*(Matches!$N$3:$N$502="Draw")*(Matches!$O$3:$O$502="Completed"))),"—") | F20: =IFERROR(IF(B20="","",IF(ISNUMBER(C20),C20-D20-E20,"—")),"—") | G20: =IFERROR(IF(B20="","",IF(ISNUMBER(D20),D20*Setup!$B$8+E20*Setup!$B$9+F20*Setup!$B$10,"—")),"—") | H20: =IFERROR(IF(B20="","",SUMPRODUCT((Matches!$B$3:$B$502=$B$3)*(Matches!$D$3:$D$502=B20)*(Matches!$O$3:$O$502="Completed")*IF(ISNUMBER(Matches!$L$3:$L$502),Matches!$L$3:$L$502,0))+SUMPRODUCT((Matches!$B$3:$B$502=$B$3)*(Matches!$E$3:$E$502=B20)*(Matches!$O$3:$O$502="Completed")*IF(ISNUMBER(Matches!$M$3:$M$502),Matches!$M$3:$M$502,0))),"—") | I20: =IFERROR(IF(B20="","",SUMPRODUCT((Matches!$B$3:$B$502=$B$3)*(Matches!$D$3:$D$502=B20)*(Matches!$O$3:$O$502="Completed")*IF(ISNUMBER(Matches!$M$3:$M$502),Matches!$M$3:$M$502,0))+SUMPRODUCT((Matches!$B$3:$B$502=$B$3)*(Matches!$E$3:$E$502=B20)*(Matches!$O$3:$O$502="Completed")*IF(ISNUMBER(Matches!$L$3:$L$502),Matches!$L$3:$L$502,0))),"—") | J20: =IFERROR(IF(B20="","",IF(ISNUMBER(H20),H20-I20,"—")),"—")
B21: =IFERROR(INDEX(Teams!$B$3:$B$52,SMALL(IF(Teams!$A$3:$A$52="A",ROW(Teams!$A$3:$A$52)-ROW(Teams!$A$3)+1),15)),"") | C21: =IFERROR(IF(B21="","",SUMPRODUCT((Matches!$B$3:$B$502=$B$3)*(Matches!$D$3:$D$502=B21)*(Matches!$O$3:$O$502="Completed"))+SUMPRODUCT((Matches!$B$3:$B$502=$B$3)*(Matches!$E$3:$E$502=B21)*(Matches!$O$3:$O$502="Completed"))),"—") | D21: =IFERROR(IF(B21="","",SUMPRODUCT((Matches!$B$3:$B$502=$B$3)*(Matches!$D$3:$D$502=B21)*(Matches!$N$3:$N$502=B21)*(Matches!$O$3:$O$502="Completed"))+SUMPRODUCT((Matches!$B$3:$B$502=$B$3)*(Matches!$E$3:$E$502=B21)*(Matches!$N$3:$N$502=B21)*(Matches!$O$3:$O$502="Completed"))),"—") | E21: =IFERROR(IF(B21="","",SUMPRODUCT((Matches!$B$3:$B$502=$B$3)*(Matches!$D$3:$D$502=B21)*(Matches!$N$3:$N$502="Draw")*(Matches!$O$3:$O$502="Completed"))+SUMPRODUCT((Matches!$B$3:$B$502=$B$3)*(Matches!$E$3:$E$502=B21)*(Matches!$N$3:$N$502="Draw")*(Matches!$O$3:$O$502="Completed"))),"—") | F21: =IFERROR(IF(B21="","",IF(ISNUMBER(C21),C21-D21-E21,"—")),"—") | G21: =IFERROR(IF(B21="","",IF(ISNUMBER(D21),D21*Setup!$B$8+E21*Setup!$B$9+F21*Setup!$B$10,"—")),"—") | H21: =IFERROR(IF(B21="","",SUMPRODUCT((Matches!$B$3:$B$502=$B$3)*(Matches!$D$3:$D$502=B21)*(Matches!$O$3:$O$502="Completed")*IF(ISNUMBER(Matches!$L$3:$L$502),Matches!$L$3:$L$502,0))+SUMPRODUCT((Matches!$B$3:$B$502=$B$3)*(Matches!$E$3:$E$502=B21)*(Matches!$O$3:$O$502="Completed")*IF(ISNUMBER(Matches!$M$3:$M$502),Matches!$M$3:$M$502,0))),"—") | I21: =IFERROR(IF(B21="","",SUMPRODUCT((Matches!$B$3:$B$502=$B$3)*(Matches!$D$3:$D$502=B21)*(Matches!$O$3:$O$502="Completed")*IF(ISNUMBER(Matches!$M$3:$M$502),Matches!$M$3:$M$502,0))+SUMPRODUCT((Matches!$B$3:$B$502=$B$3)*(Matches!$E$3:$E$502=B21)*(Matches!$O$3:$O$502="Completed")*IF(ISNUMBER(Matches!$L$3:$L$502),Matches!$L$3:$L$502,0))),"—") | J21: =IFERROR(IF(B21="","",IF(ISNUMBER(H21),H21-I21,"—")),"—")
B22: =IFERROR(INDEX(Teams!$B$3:$B$52,SMALL(IF(Teams!$A$3:$A$52="A",ROW(Teams!$A$3:$A$52)-ROW(Teams!$A$3)+1),16)),"") | C22: =IFERROR(IF(B22="","",SUMPRODUCT((Matches!$B$3:$B$502=$B$3)*(Matches!$D$3:$D$502=B22)*(Matches!$O$3:$O$502="Completed"))+SUMPRODUCT((Matches!$B$3:$B$502=$B$3)*(Matches!$E$3:$E$502=B22)*(Matches!$O$3:$O$502="Completed"))),"—") | D22: =IFERROR(IF(B22="","",SUMPRODUCT((Matches!$B$3:$B$502=$B$3)*(Matches!$D$3:$D$502=B22)*(Matches!$N$3:$N$502=B22)*(Matches!$O$3:$O$502="Completed"))+SUMPRODUCT((Matches!$B$3:$B$502=$B$3)*(Matches!$E$3:$E$502=B22)*(Matches!$N$3:$N$502=B22)*(Matches!$O$3:$O$502="Completed"))),"—") | E22: =IFERROR(IF(B22="","",SUMPRODUCT((Matches!$B$3:$B$502=$B$3)*(Matches!$D$3:$D$502=B22)*(Matches!$N$3:$N$502="Draw")*(Matches!$O$3:$O$502="Completed"))+SUMPRODUCT((Matches!$B$3:$B$502=$B$3)*(Matches!$E$3:$E$502=B22)*(Matches!$N$3:$N$502="Draw")*(Matches!$O$3:$O$502="Completed"))),"—") | F22: =IFERROR(IF(B22="","",IF(ISNUMBER(C22),C22-D22-E22,"—")),"—") | G22: =IFERROR(IF(B22="","",IF(ISNUMBER(D22),D22*Setup!$B$8+E22*Setup!$B$9+F22*Setup!$B$10,"—")),"—") | H22: =IFERROR(IF(B22="","",SUMPRODUCT((Matches!$B$3:$B$502=$B$3)*(Matches!$D$3:$D$502=B22)*(Matches!$O$3:$O$502="Completed")*IF(ISNUMBER(Matches!$L$3:$L$502),Matches!$L$3:$L$502,0))+SUMPRODUCT((Matches!$B$3:$B$502=$B$3)*(Matches!$E$3:$E$502=B22)*(Matches!$O$3:$O$502="Completed")*IF(ISNUMBER(Matches!$M$3:$M$502),Matches!$M$3:$M$502,0))),"—") | I22: =IFERROR(IF(B22="","",SUMPRODUCT((Matches!$B$3:$B$502=$B$3)*(Matches!$D$3:$D$502=B22)*(Matches!$O$3:$O$502="Completed")*IF(ISNUMBER(Matches!$M$3:$M$502),Matches!$M$3:$M$502,0))+SUMPRODUCT((Matches!$B$3:$B$502=$B$3)*(Matches!$E$3:$E$502=B22)*(Matches!$O$3:$O$502="Completed")*IF(ISNUMBER(Matches!$L$3:$L$502),Matches!$L$3:$L$502,0))),"—") | J22: =IFERROR(IF(B22="","",IF(ISNUMBER(H22),H22-I22,"—")),"—")
B23: =IFERROR(INDEX(Teams!$B$3:$B$52,SMALL(IF(Teams!$A$3:$A$52="A",ROW(Teams!$A$3:$A$52)-ROW(Teams!$A$3)+1),17)),"") | C23: =IFERROR(IF(B23="","",SUMPRODUCT((Matches!$B$3:$B$502=$B$3)*(Matches!$D$3:$D$502=B23)*(Matches!$O$3:$O$502="Completed"))+SUMPRODUCT((Matches!$B$3:$B$502=$B$3)*(Matches!$E$3:$E$502=B23)*(Matches!$O$3:$O$502="Completed"))),"—") | D23: =IFERROR(IF(B23="","",SUMPRODUCT((Matches!$B$3:$B$502=$B$3)*(Matches!$D$3:$D$502=B23)*(Matches!$N$3:$N$502=B23)*(Matches!$O$3:$O$502="Completed"))+SUMPRODUCT((Matches!$B$3:$B$502=$B$3)*(Matches!$E$3:$E$502=B23)*(Matches!$N$3:$N$502=B23)*(Matches!$O$3:$O$502="Completed"))),"—") | E23: =IFERROR(IF(B23="","",SUMPRODUCT((Matches!$B$3:$B$502=$B$3)*(Matches!$D$3:$D$502=B23)*(Matches!$N$3:$N$502="Draw")*(Matches!$O$3:$O$502="Completed"))+SUMPRODUCT((Matches!$B$3:$B$502=$B$3)*(Matches!$E$3:$E$502=B23)*(Matches!$N$3:$N$502="Draw")*(Matches!$O$3:$O$502="Completed"))),"—") | F23: =IFERROR(IF(B23="","",IF(ISNUMBER(C23),C23-D23-E23,"—")),"—") | G23: =IFERROR(IF(B23="","",IF(ISNUMBER(D23),D23*Setup!$B$8+E23*Setup!$B$9+F23*Setup!$B$10,"—")),"—") | H23: =IFERROR(IF(B23="","",SUMPRODUCT((Matches!$B$3:$B$502=$B$3)*(Matches!$D$3:$D$502=B23)*(Matches!$O$3:$O$502="Completed")*IF(ISNUMBER(Matches!$L$3:$L$502),Matches!$L$3:$L$502,0))+SUMPRODUCT((Matches!$B$3:$B$502=$B$3)*(Matches!$E$3:$E$502=B23)*(Matches!$O$3:$O$502="Completed")*IF(ISNUMBER(Matches!$M$3:$M$502),Matches!$M$3:$M$502,0))),"—") | I23: =IFERROR(IF(B23="","",SUMPRODUCT((Matches!$B$3:$B$502=$B$3)*(Matches!$D$3:$D$502=B23)*(Matches!$O$3:$O$502="Completed")*IF(ISNUMBER(Matches!$M$3:$M$502),Matches!$M$3:$M$502,0))+SUMPRODUCT((Matches!$B$3:$B$502=$B$3)*(Matches!$E$3:$E$502=B23)*(Matches!$O$3:$O$502="Completed")*IF(ISNUMBER(Matches!$L$3:$L$502),Matches!$L$3:$L$502,0))),"—") | J23: =IFERROR(IF(B23="","",IF(ISNUMBER(H23),H23-I23,"—")),"—")
B24: =IFERROR(INDEX(Teams!$B$3:$B$52,SMALL(IF(Teams!$A$3:$A$52="A",ROW(Teams!$A$3:$A$52)-ROW(Teams!$A$3)+1),18)),"") | C24: =IFERROR(IF(B24="","",SUMPRODUCT((Matches!$B$3:$B$502=$B$3)*(Matches!$D$3:$D$502=B24)*(Matches!$O$3:$O$502="Completed"))+SUMPRODUCT((Matches!$B$3:$B$502=$B$3)*(Matches!$E$3:$E$502=B24)*(Matches!$O$3:$O$502="Completed"))),"—") | D24: =IFERROR(IF(B24="","",SUMPRODUCT((Matches!$B$3:$B$502=$B$3)*(Matches!$D$3:$D$502=B24)*(Matches!$N$3:$N$502=B24)*(Matches!$O$3:$O$502="Completed"))+SUMPRODUCT((Matches!$B$3:$B$502=$B$3)*(Matches!$E$3:$E$502=B24)*(Matches!$N$3:$N$502=B24)*(Matches!$O$3:$O$502="Completed"))),"—") | E24: =IFERROR(IF(B24="","",SUMPRODUCT((Matches!$B$3:$B$502=$B$3)*(Matches!$D$3:$D$502=B24)*(Matches!$N$3:$N$502="Draw")*(Matches!$O$3:$O$502="Completed"))+SUMPRODUCT((Matches!$B$3:$B$502=$B$3)*(Matches!$E$3:$E$502=B24)*(Matches!$N$3:$N$502="Draw")*(Matches!$O$3:$O$502="Completed"))),"—") | F24: =IFERROR(IF(B24="","",IF(ISNUMBER(C24),C24-D24-E24,"—")),"—") | G24: =IFERROR(IF(B24="","",IF(ISNUMBER(D24),D24*Setup!$B$8+E24*Setup!$B$9+F24*Setup!$B$10,"—")),"—") | H24: =IFERROR(IF(B24="","",SUMPRODUCT((Matches!$B$3:$B$502=$B$3)*(Matches!$D$3:$D$502=B24)*(Matches!$O$3:$O$502="Completed")*IF(ISNUMBER(Matches!$L$3:$L$502),Matches!$L$3:$L$502,0))+SUMPRODUCT((Matches!$B$3:$B$502=$B$3)*(Matches!$E$3:$E$502=B24)*(Matches!$O$3:$O$502="Completed")*IF(ISNUMBER(Matches!$M$3:$M$502),Matches!$M$3:$M$502,0))),"—") | I24: =IFERROR(IF(B24="","",SUMPRODUCT((Matches!$B$3:$B$502=$B$3)*(Matches!$D$3:$D$502=B24)*(Matches!$O$3:$O$502="Completed")*IF(ISNUMBER(Matches!$M$3:$M$502),Matches!$M$3:$M$502,0))+SUMPRODUCT((Matches!$B$3:$B$502=$B$3)*(Matches!$E$3:$E$502=B24)*(Matches!$O$3:$O$502="Completed")*IF(ISNUMBER(Matches!$L$3:$L$502),Matches!$L$3:$L$502,0))),"—") | J24: =IFERROR(IF(B24="","",IF(ISNUMBER(H24),H24-I24,"—")),"—")
B25: =IFERROR(INDEX(Teams!$B$3:$B$52,SMALL(IF(Teams!$A$3:$A$52="A",ROW(Teams!$A$3:$A$52)-ROW(Teams!$A$3)+1),19)),"") | C25: =IFERROR(IF(B25="","",SUMPRODUCT((Matches!$B$3:$B$502=$B$3)*(Matches!$D$3:$D$502=B25)*(Matches!$O$3:$O$502="Completed"))+SUMPRODUCT((Matches!$B$3:$B$502=$B$3)*(Matches!$E$3:$E$502=B25)*(Matches!$O$3:$O$502="Completed"))),"—") | D25: =IFERROR(IF(B25="","",SUMPRODUCT((Matches!$B$3:$B$502=$B$3)*(Matches!$D$3:$D$502=B25)*(Matches!$N$3:$N$502=B25)*(Matches!$O$3:$O$502="Completed"))+SUMPRODUCT((Matches!$B$3:$B$502=$B$3)*(Matches!$E$3:$E$502=B25)*(Matches!$N$3:$N$502=B25)*(Matches!$O$3:$O$502="Completed"))),"—") | E25: =IFERROR(IF(B25="","",SUMPRODUCT((Matches!$B$3:$B$502=$B$3)*(Matches!$D$3:$D$502=B25)*(Matches!$N$3:$N$502="Draw")*(Matches!$O$3:$O$502="Completed"))+SUMPRODUCT((Matches!$B$3:$B$502=$B$3)*(Matches!$E$3:$E$502=B25)*(Matches!$N$3:$N$502="Draw")*(Matches!$O$3:$O$502="Completed"))),"—") | F25: =IFERROR(IF(B25="","",IF(ISNUMBER(C25),C25-D25-E25,"—")),"—") | G25: =IFERROR(IF(B25="","",IF(ISNUMBER(D25),D25*Setup!$B$8+E25*Setup!$B$9+F25*Setup!$B$10,"—")),"—") | H25: =IFERROR(IF(B25="","",SUMPRODUCT((Matches!$B$3:$B$502=$B$3)*(Matches!$D$3:$D$502=B25)*(Matches!$O$3:$O$502="Completed")*IF(ISNUMBER(Matches!$L$3:$L$502),Matches!$L$3:$L$502,0))+SUMPRODUCT((Matches!$B$3:$B$502=$B$3)*(Matches!$E$3:$E$502=B25)*(Matches!$O$3:$O$502="Completed")*IF(ISNUMBER(Matches!$M$3:$M$502),Matches!$M$3:$M$502,0))),"—") | I25: =IFERROR(IF(B25="","",SUMPRODUCT((Matches!$B$3:$B$502=$B$3)*(Matches!$D$3:$D$502=B25)*(Matches!$O$3:$O$502="Completed")*IF(ISNUMBER(Matches!$M$3:$M$502),Matches!$M$3:$M$502,0))+SUMPRODUCT((Matches!$B$3:$B$502=$B$3)*(Matches!$E$3:$E$502=B25)*(Matches!$O$3:$O$502="Completed")*IF(ISNUMBER(Matches!$L$3:$L$502),Matches!$L$3:$L$502,0))),"—") | J25: =IFERROR(IF(B25="","",IF(ISNUMBER(H25),H25-I25,"—")),"—")
B26: =IFERROR(INDEX(Teams!$B$3:$B$52,SMALL(IF(Teams!$A$3:$A$52="A",ROW(Teams!$A$3:$A$52)-ROW(Teams!$A$3)+1),20)),"") | C26: =IFERROR(IF(B26="","",SUMPRODUCT((Matches!$B$3:$B$502=$B$3)*(Matches!$D$3:$D$502=B26)*(Matches!$O$3:$O$502="Completed"))+SUMPRODUCT((Matches!$B$3:$B$502=$B$3)*(Matches!$E$3:$E$502=B26)*(Matches!$O$3:$O$502="Completed"))),"—") | D26: =IFERROR(IF(B26="","",SUMPRODUCT((Matches!$B$3:$B$502=$B$3)*(Matches!$D$3:$D$502=B26)*(Matches!$N$3:$N$502=B26)*(Matches!$O$3:$O$502="Completed"))+SUMPRODUCT((Matches!$B$3:$B$502=$B$3)*(Matches!$E$3:$E$502=B26)*(Matches!$N$3:$N$502=B26)*(Matches!$O$3:$O$502="Completed"))),"—") | E26: =IFERROR(IF(B26="","",SUMPRODUCT((Matches!$B$3:$B$502=$B$3)*(Matches!$D$3:$D$502=B26)*(Matches!$N$3:$N$502="Draw")*(Matches!$O$3:$O$502="Completed"))+SUMPRODUCT((Matches!$B$3:$B$502=$B$3)*(Matches!$E$3:$E$502=B26)*(Matches!$N$3:$N$502="Draw")*(Matches!$O$3:$O$502="Completed"))),"—") | F26: =IFERROR(IF(B26="","",IF(ISNUMBER(C26),C26-D26-E26,"—")),"—") | G26: =IFERROR(IF(B26="","",IF(ISNUMBER(D26),D26*Setup!$B$8+E26*Setup!$B$9+F26*Setup!$B$10,"—")),"—") | H26: =IFERROR(IF(B26="","",SUMPRODUCT((Matches!$B$3:$B$502=$B$3)*(Matches!$D$3:$D$502=B26)*(Matches!$O$3:$O$502="Completed")*IF(ISNUMBER(Matches!$L$3:$L$502),Matches!$L$3:$L$502,0))+SUMPRODUCT((Matches!$B$3:$B$502=$B$3)*(Matches!$E$3:$E$502=B26)*(Matches!$O$3:$O$502="Completed")*IF(ISNUMBER(Matches!$M$3:$M$502),Matches!$M$3:$M$502,0))),"—") | I26: =IFERROR(IF(B26="","",SUMPRODUCT((Matches!$B$3:$B$502=$B$3)*(Matches!$D$3:$D$502=B26)*(Matches!$O$3:$O$502="Completed")*IF(ISNUMBER(Matches!$M$3:$M$502),Matches!$M$3:$M$502,0))+SUMPRODUCT((Matches!$B$3:$B$502=$B$3)*(Matches!$E$3:$E$502=B26)*(Matches!$O$3:$O$502="Completed")*IF(ISNUMBER(Matches!$L$3:$L$502),Matches!$L$3:$L$502,0))),"—") | J26: =IFERROR(IF(B26="","",IF(ISNUMBER(H26),H26-I26,"—")),"—")
A30: DIVISION B
A31: Pos | B31: Team | C31: Played | D31: Won | E31: Drawn | F31: Lost | G31: Points | H31: GF | I31: GA | J31: Diff
B32: =IFERROR(INDEX(Teams!$B$3:$B$52,SMALL(IF(Teams!$A$3:$A$52="B",ROW(Teams!$A$3:$A$52)-ROW(Teams!$A$3)+1),1)),"") | C32: =IFERROR(IF(B32="","",SUMPRODUCT((Matches!$B$3:$B$502=$B$3)*(Matches!$D$3:$D$502=B32)*(Matches!$O$3:$O$502="Completed"))+SUMPRODUCT((Matches!$B$3:$B$502=$B$3)*(Matches!$E$3:$E$502=B32)*(Matches!$O$3:$O$502="Completed"))),"—") | D32: =IFERROR(IF(B32="","",SUMPRODUCT((Matches!$B$3:$B$502=$B$3)*(Matches!$D$3:$D$502=B32)*(Matches!$N$3:$N$502=B32)*(Matches!$O$3:$O$502="Completed"))+SUMPRODUCT((Matches!$B$3:$B$502=$B$3)*(Matches!$E$3:$E$502=B32)*(Matches!$N$3:$N$502=B32)*(Matches!$O$3:$O$502="Completed"))),"—") | E32: =IFERROR(IF(B32="","",SUMPRODUCT((Matches!$B$3:$B$502=$B$3)*(Matches!$D$3:$D$502=B32)*(Matches!$N$3:$N$502="Draw")*(Matches!$O$3:$O$502="Completed"))+SUMPRODUCT((Matches!$B$3:$B$502=$B$3)*(Matches!$E$3:$E$502=B32)*(Matches!$N$3:$N$502="Draw")*(Matches!$O$3:$O$502="Completed"))),"—") | F32: =IFERROR(IF(B32="","",IF(ISNUMBER(C32),C32-D32-E32,"—")),"—") | G32: =IFERROR(IF(B32="","",IF(ISNUMBER(D32),D32*Setup!$B$8+E32*Setup!$B$9+F32*Setup!$B$10,"—")),"—") | H32: =IFERROR(IF(B32="","",SUMPRODUCT((Matches!$B$3:$B$502=$B$3)*(Matches!$D$3:$D$502=B32)*(Matches!$O$3:$O$502="Completed")*IF(ISNUMBER(Matches!$L$3:$L$502),Matches!$L$3:$L$502,0))+SUMPRODUCT((Matches!$B$3:$B$502=$B$3)*(Matches!$E$3:$E$502=B32)*(Matches!$O$3:$O$502="Completed")*IF(ISNUMBER(Matches!$M$3:$M$502),Matches!$M$3:$M$502,0))),"—") | I32: =IFERROR(IF(B32="","",SUMPRODUCT((Matches!$B$3:$B$502=$B$3)*(Matches!$D$3:$D$502=B32)*(Matches!$O$3:$O$502="Completed")*IF(ISNUMBER(Matches!$M$3:$M$502),Matches!$M$3:$M$502,0))+SUMPRODUCT((Matches!$B$3:$B$502=$B$3)*(Matches!$E$3:$E$502=B32)*(Matches!$O$3:$O$502="Completed")*IF(ISNUMBER(Matches!$L$3:$L$502),Matches!$L$3:$L$502,0))),"—") | J32: =IFERROR(IF(B32="","",IF(ISNUMBER(H32),H32-I32,"—")),"—")
B33: =IFERROR(INDEX(Teams!$B$3:$B$52,SMALL(IF(Teams!$A$3:$A$52="B",ROW(Teams!$A$3:$A$52)-ROW(Teams!$A$3)+1),2)),"") | C33: =IFERROR(IF(B33="","",SUMPRODUCT((Matches!$B$3:$B$502=$B$3)*(Matches!$D$3:$D$502=B33)*(Matches!$O$3:$O$502="Completed"))+SUMPRODUCT((Matches!$B$3:$B$502=$B$3)*(Matches!$E$3:$E$502=B33)*(Matches!$O$3:$O$502="Completed"))),"—") | D33: =IFERROR(IF(B33="","",SUMPRODUCT((Matches!$B$3:$B$502=$B$3)*(Matches!$D$3:$D$502=B33)*(Matches!$N$3:$N$502=B33)*(Matches!$O$3:$O$502="Completed"))+SUMPRODUCT((Matches!$B$3:$B$502=$B$3)*(Matches!$E$3:$E$502=B33)*(Matches!$N$3:$N$502=B33)*(Matches!$O$3:$O$502="Completed"))),"—") | E33: =IFERROR(IF(B33="","",SUMPRODUCT((Matches!$B$3:$B$502=$B$3)*(Matches!$D$3:$D$502=B33)*(Matches!$N$3:$N$502="Draw")*(Matches!$O$3:$O$502="Completed"))+SUMPRODUCT((Matches!$B$3:$B$502=$B$3)*(Matches!$E$3:$E$502=B33)*(Matches!$N$3:$N$502="Draw")*(Matches!$O$3:$O$502="Completed"))),"—") | F33: =IFERROR(IF(B33="","",IF(ISNUMBER(C33),C33-D33-E33,"—")),"—") | G33: =IFERROR(IF(B33="","",IF(ISNUMBER(D33),D33*Setup!$B$8+E33*Setup!$B$9+F33*Setup!$B$10,"—")),"—") | H33: =IFERROR(IF(B33="","",SUMPRODUCT((Matches!$B$3:$B$502=$B$3)*(Matches!$D$3:$D$502=B33)*(Matches!$O$3:$O$502="Completed")*IF(ISNUMBER(Matches!$L$3:$L$502),Matches!$L$3:$L$502,0))+SUMPRODUCT((Matches!$B$3:$B$502=$B$3)*(Matches!$E$3:$E$502=B33)*(Matches!$O$3:$O$502="Completed")*IF(ISNUMBER(Matches!$M$3:$M$502),Matches!$M$3:$M$502,0))),"—") | I33: =IFERROR(IF(B33="","",SUMPRODUCT((Matches!$B$3:$B$502=$B$3)*(Matches!$D$3:$D$502=B33)*(Matches!$O$3:$O$502="Completed")*IF(ISNUMBER(Matches!$M$3:$M$502),Matches!$M$3:$M$502,0))+SUMPRODUCT((Matches!$B$3:$B$502=$B$3)*(Matches!$E$3:$E$502=B33)*(Matches!$O$3:$O$502="Completed")*IF(ISNUMBER(Matches!$L$3:$L$502),Matches!$L$3:$L$502,0))),"—") | J33: =IFERROR(IF(B33="","",IF(ISNUMBER(H33),H33-I33,"—")),"—")
B34: =IFERROR(INDEX(Teams!$B$3:$B$52,SMALL(IF(Teams!$A$3:$A$52="B",ROW(Teams!$A$3:$A$52)-ROW(Teams!$A$3)+1),3)),"") | C34: =IFERROR(IF(B34="","",SUMPRODUCT((Matches!$B$3:$B$502=$B$3)*(Matches!$D$3:$D$502=B34)*(Matches!$O$3:$O$502="Completed"))+SUMPRODUCT((Matches!$B$3:$B$502=$B$3)*(Matches!$E$3:$E$502=B34)*(Matches!$O$3:$O$502="Completed"))),"—") | D34: =IFERROR(IF(B34="","",SUMPRODUCT((Matches!$B$3:$B$502=$B$3)*(Matches!$D$3:$D$502=B34)*(Matches!$N$3:$N$502=B34)*(Matches!$O$3:$O$502="Completed"))+SUMPRODUCT((Matches!$B$3:$B$502=$B$3)*(Matches!$E$3:$E$502=B34)*(Matches!$N$3:$N$502=B34)*(Matches!$O$3:$O$502="Completed"))),"—") | E34: =IFERROR(IF(B34="","",SUMPRODUCT((Matches!$B$3:$B$502=$B$3)*(Matches!$D$3:$D$502=B34)*(Matches!$N$3:$N$502="Draw")*(Matches!$O$3:$O$502="Completed"))+SUMPRODUCT((Matches!$B$3:$B$502=$B$3)*(Matches!$E$3:$E$502=B34)*(Matches!$N$3:$N$502="Draw")*(Matches!$O$3:$O$502="Completed"))),"—") | F34: =IFERROR(IF(B34="","",IF(ISNUMBER(C34),C34-D34-E34,"—")),"—") | G34: =IFERROR(IF(B34="","",IF(ISNUMBER(D34),D34*Setup!$B$8+E34*Setup!$B$9+F34*Setup!$B$10,"—")),"—") | H34: =IFERROR(IF(B34="","",SUMPRODUCT((Matches!$B$3:$B$502=$B$3)*(Matches!$D$3:$D$502=B34)*(Matches!$O$3:$O$502="Completed")*IF(ISNUMBER(Matches!$L$3:$L$502),Matches!$L$3:$L$502,0))+SUMPRODUCT((Matches!$B$3:$B$502=$B$3)*(Matches!$E$3:$E$502=B34)*(Matches!$O$3:$O$502="Completed")*IF(ISNUMBER(Matches!$M$3:$M$502),Matches!$M$3:$M$502,0))),"—") | I34: =IFERROR(IF(B34="","",SUMPRODUCT((Matches!$B$3:$B$502=$B$3)*(Matches!$D$3:$D$502=B34)*(Matches!$O$3:$O$502="Completed")*IF(ISNUMBER(Matches!$M$3:$M$502),Matches!$M$3:$M$502,0))+SUMPRODUCT((Matches!$B$3:$B$502=$B$3)*(Matches!$E$3:$E$502=B34)*(Matches!$O$3:$O$502="Completed")*IF(ISNUMBER(Matches!$L$3:$L$502),Matches!$L$3:$L$502,0))),"—") | J34: =IFERROR(IF(B34="","",IF(ISNUMBER(H34),H34-I34,"—")),"—")
B35: =IFERROR(INDEX(Teams!$B$3:$B$52,SMALL(IF(Teams!$A$3:$A$52="B",ROW(Teams!$A$3:$A$52)-ROW(Teams!$A$3)+1),4)),"") | C35: =IFERROR(IF(B35="","",SUMPRODUCT((Matches!$B$3:$B$502=$B$3)*(Matches!$D$3:$D$502=B35)*(Matches!$O$3:$O$502="Completed"))+SUMPRODUCT((Matches!$B$3:$B$502=$B$3)*(Matches!$E$3:$E$502=B35)*(Matches!$O$3:$O$502="Completed"))),"—") | D35: =IFERROR(IF(B35="","",SUMPRODUCT((Matches!$B$3:$B$502=$B$3)*(Matches!$D$3:$D$502=B35)*(Matches!$N$3:$N$502=B35)*(Matches!$O$3:$O$502="Completed"))+SUMPRODUCT((Matches!$B$3:$B$502=$B$3)*(Matches!$E$3:$E$502=B35)*(Matches!$N$3:$N$502=B35)*(Matches!$O$3:$O$502="Completed"))),"—") | E35: =IFERROR(IF(B35="","",SUMPRODUCT((Matches!$B$3:$B$502=$B$3)*(Matches!$D$3:$D$502=B35)*(Matches!$N$3:$N$502="Draw")*(Matches!$O$3:$O$502="Completed"))+SUMPRODUCT((Matches!$B$3:$B$502=$B$3)*(Matches!$E$3:$E$502=B35)*(Matches!$N$3:$N$502="Draw")*(Matches!$O$3:$O$502="Completed"))),"—") | F35: =IFERROR(IF(B35="","",IF(ISNUMBER(C35),C35-D35-E35,"—")),"—") | G35: =IFERROR(IF(B35="","",IF(ISNUMBER(D35),D35*Setup!$B$8+E35*Setup!$B$9+F35*Setup!$B$10,"—")),"—") | H35: =IFERROR(IF(B35="","",SUMPRODUCT((Matches!$B$3:$B$502=$B$3)*(Matches!$D$3:$D$502=B35)*(Matches!$O$3:$O$502="Completed")*IF(ISNUMBER(Matches!$L$3:$L$502),Matches!$L$3:$L$502,0))+SUMPRODUCT((Matches!$B$3:$B$502=$B$3)*(Matches!$E$3:$E$502=B35)*(Matches!$O$3:$O$502="Completed")*IF(ISNUMBER(Matches!$M$3:$M$502),Matches!$M$3:$M$502,0))),"—") | I35: =IFERROR(IF(B35="","",SUMPRODUCT((Matches!$B$3:$B$502=$B$3)*(Matches!$D$3:$D$502=B35)*(Matches!$O$3:$O$502="Completed")*IF(ISNUMBER(Matches!$M$3:$M$502),Matches!$M$3:$M$502,0))+SUMPRODUCT((Matches!$B$3:$B$502=$B$3)*(Matches!$E$3:$E$502=B35)*(Matches!$O$3:$O$502="Completed")*IF(ISNUMBER(Matches!$L$3:$L$502),Matches!$L$3:$L$502,0))),"—") | J35: =IFERROR(IF(B35="","",IF(ISNUMBER(H35),H35-I35,"—")),"—")
B36: =IFERROR(INDEX(Teams!$B$3:$B$52,SMALL(IF(Teams!$A$3:$A$52="B",ROW(Teams!$A$3:$A$52)-ROW(Teams!$A$3)+1),5)),"") | C36: =IFERROR(IF(B36="","",SUMPRODUCT((Matches!$B$3:$B$502=$B$3)*(Matches!$D$3:$D$502=B36)*(Matches!$O$3:$O$502="Completed"))+SUMPRODUCT((Matches!$B$3:$B$502=$B$3)*(Matches!$E$3:$E$502=B36)*(Matches!$O$3:$O$502="Completed"))),"—") | D36: =IFERROR(IF(B36="","",SUMPRODUCT((Matches!$B$3:$B$502=$B$3)*(Matches!$D$3:$D$502=B36)*(Matches!$N$3:$N$502=B36)*(Matches!$O$3:$O$502="Completed"))+SUMPRODUCT((Matches!$B$3:$B$502=$B$3)*(Matches!$E$3:$E$502=B36)*(Matches!$N$3:$N$502=B36)*(Matches!$O$3:$O$502="Completed"))),"—") | E36: =IFERROR(IF(B36="","",SUMPRODUCT((Matches!$B$3:$B$502=$B$3)*(Matches!$D$3:$D$502=B36)*(Matches!$N$3:$N$502="Draw")*(Matches!$O$3:$O$502="Completed"))+SUMPRODUCT((Matches!$B$3:$B$502=$B$3)*(Matches!$E$3:$E$502=B36)*(Matches!$N$3:$N$502="Draw")*(Matches!$O$3:$O$502="Completed"))),"—") | F36: =IFERROR(IF(B36="","",IF(ISNUMBER(C36),C36-D36-E36,"—")),"—") | G36: =IFERROR(IF(B36="","",IF(ISNUMBER(D36),D36*Setup!$B$8+E36*Setup!$B$9+F36*Setup!$B$10,"—")),"—") | H36: =IFERROR(IF(B36="","",SUMPRODUCT((Matches!$B$3:$B$502=$B$3)*(Matches!$D$3:$D$502=B36)*(Matches!$O$3:$O$502="Completed")*IF(ISNUMBER(Matches!$L$3:$L$502),Matches!$L$3:$L$502,0))+SUMPRODUCT((Matches!$B$3:$B$502=$B$3)*(Matches!$E$3:$E$502=B36)*(Matches!$O$3:$O$502="Completed")*IF(ISNUMBER(Matches!$M$3:$M$502),Matches!$M$3:$M$502,0))),"—") | I36: =IFERROR(IF(B36="","",SUMPRODUCT((Matches!$B$3:$B$502=$B$3)*(Matches!$D$3:$D$502=B36)*(Matches!$O$3:$O$502="Completed")*IF(ISNUMBER(Matches!$M$3:$M$502),Matches!$M$3:$M$502,0))+SUMPRODUCT((Matches!$B$3:$B$502=$B$3)*(Matches!$E$3:$E$502=B36)*(Matches!$O$3:$O$502="Completed")*IF(ISNUMBER(Matches!$L$3:$L$502),Matches!$L$3:$L$502,0))),"—") | J36: =IFERROR(IF(B36="","",IF(ISNUMBER(H36),H36-I36,"—")),"—")
B37: =IFERROR(INDEX(Teams!$B$3:$B$52,SMALL(IF(Teams!$A$3:$A$52="B",ROW(Teams!$A$3:$A$52)-ROW(Teams!$A$3)+1),6)),"") | C37: =IFERROR(IF(B37="","",SUMPRODUCT((Matches!$B$3:$B$502=$B$3)*(Matches!$D$3:$D$502=B37)*(Matches!$O$3:$O$502="Completed"))+SUMPRODUCT((Matches!$B$3:$B$502=$B$3)*(Matches!$E$3:$E$502=B37)*(Matches!$O$3:$O$502="Completed"))),"—") | D37: =IFERROR(IF(B37="","",SUMPRODUCT((Matches!$B$3:$B$502=$B$3)*(Matches!$D$3:$D$502=B37)*(Matches!$N$3:$N$502=B37)*(Matches!$O$3:$O$502="Completed"))+SUMPRODUCT((Matches!$B$3:$B$502=$B$3)*(Matches!$E$3:$E$502=B37)*(Matches!$N$3:$N$502=B37)*(Matches!$O$3:$O$502="Completed"))),"—") | E37: =IFERROR(IF(B37="","",SUMPRODUCT((Matches!$B$3:$B$502=$B$3)*(Matches!$D$3:$D$502=B37)*(Matches!$N$3:$N$502="Draw")*(Matches!$O$3:$O$502="Completed"))+SUMPRODUCT((Matches!$B$3:$B$502=$B$3)*(Matches!$E$3:$E$502=B37)*(Matches!$N$3:$N$502="Draw")*(Matches!$O$3:$O$502="Completed"))),"—") | F37: =IFERROR(IF(B37="","",IF(ISNUMBER(C37),C37-D37-E37,"—")),"—") | G37: =IFERROR(IF(B37="","",IF(ISNUMBER(D37),D37*Setup!$B$8+E37*Setup!$B$9+F37*Setup!$B$10,"—")),"—") | H37: =IFERROR(IF(B37="","",SUMPRODUCT((Matches!$B$3:$B$502=$B$3)*(Matches!$D$3:$D$502=B37)*(Matches!$O$3:$O$502="Completed")*IF(ISNUMBER(Matches!$L$3:$L$502),Matches!$L$3:$L$502,0))+SUMPRODUCT((Matches!$B$3:$B$502=$B$3)*(Matches!$E$3:$E$502=B37)*(Matches!$O$3:$O$502="Completed")*IF(ISNUMBER(Matches!$M$3:$M$502),Matches!$M$3:$M$502,0))),"—") | I37: =IFERROR(IF(B37="","",SUMPRODUCT((Matches!$B$3:$B$502=$B$3)*(Matches!$D$3:$D$502=B37)*(Matches!$O$3:$O$502="Completed")*IF(ISNUMBER(Matches!$M$3:$M$502),Matches!$M$3:$M$502,0))+SUMPRODUCT((Matches!$B$3:$B$502=$B$3)*(Matches!$E$3:$E$502=B37)*(Matches!$O$3:$O$502="Completed")*IF(ISNUMBER(Matches!$L$3:$L$502),Matches!$L$3:$L$502,0))),"—") | J37: =IFERROR(IF(B37="","",IF(ISNUMBER(H37),H37-I37,"—")),"—")
B38: =IFERROR(INDEX(Teams!$B$3:$B$52,SMALL(IF(Teams!$A$3:$A$52="B",ROW(Teams!$A$3:$A$52)-ROW(Teams!$A$3)+1),7)),"") | C38: =IFERROR(IF(B38="","",SUMPRODUCT((Matches!$B$3:$B$502=$B$3)*(Matches!$D$3:$D$502=B38)*(Matches!$O$3:$O$502="Completed"))+SUMPRODUCT((Matches!$B$3:$B$502=$B$3)*(Matches!$E$3:$E$502=B38)*(Matches!$O$3:$O$502="Completed"))),"—") | D38: =IFERROR(IF(B38="","",SUMPRODUCT((Matches!$B$3:$B$502=$B$3)*(Matches!$D$3:$D$502=B38)*(Matches!$N$3:$N$502=B38)*(Matches!$O$3:$O$502="Completed"))+SUMPRODUCT((Matches!$B$3:$B$502=$B$3)*(Matches!$E$3:$E$502=B38)*(Matches!$N$3:$N$502=B38)*(Matches!$O$3:$O$502="Completed"))),"—") | E38: =IFERROR(IF(B38="","",SUMPRODUCT((Matches!$B$3:$B$502=$B$3)*(Matches!$D$3:$D$502=B38)*(Matches!$N$3:$N$502="Draw")*(Matches!$O$3:$O$502="Completed"))+SUMPRODUCT((Matches!$B$3:$B$502=$B$3)*(Matches!$E$3:$E$502=B38)*(Matches!$N$3:$N$502="Draw")*(Matches!$O$3:$O$502="Completed"))),"—") | F38: =IFERROR(IF(B38="","",IF(ISNUMBER(C38),C38-D38-E38,"—")),"—") | G38: =IFERROR(IF(B38="","",IF(ISNUMBER(D38),D38*Setup!$B$8+E38*Setup!$B$9+F38*Setup!$B$10,"—")),"—") | H38: =IFERROR(IF(B38="","",SUMPRODUCT((Matches!$B$3:$B$502=$B$3)*(Matches!$D$3:$D$502=B38)*(Matches!$O$3:$O$502="Completed")*IF(ISNUMBER(Matches!$L$3:$L$502),Matches!$L$3:$L$502,0))+SUMPRODUCT((Matches!$B$3:$B$502=$B$3)*(Matches!$E$3:$E$502=B38)*(Matches!$O$3:$O$502="Completed")*IF(ISNUMBER(Matches!$M$3:$M$502),Matches!$M$3:$M$502,0))),"—") | I38: =IFERROR(IF(B38="","",SUMPRODUCT((Matches!$B$3:$B$502=$B$3)*(Matches!$D$3:$D$502=B38)*(Matches!$O$3:$O$502="Completed")*IF(ISNUMBER(Matches!$M$3:$M$502),Matches!$M$3:$M$502,0))+SUMPRODUCT((Matches!$B$3:$B$502=$B$3)*(Matches!$E$3:$E$502=B38)*(Matches!$O$3:$O$502="Completed")*IF(ISNUMBER(Matches!$L$3:$L$502),Matches!$L$3:$L$502,0))),"—") | J38: =IFERROR(IF(B38="","",IF(ISNUMBER(H38),H38-I38,"—")),"—")
B39: =IFERROR(INDEX(Teams!$B$3:$B$52,SMALL(IF(Teams!$A$3:$A$52="B",ROW(Teams!$A$3:$A$52)-ROW(Teams!$A$3)+1),8)),"") | C39: =IFERROR(IF(B39="","",SUMPRODUCT((Matches!$B$3:$B$502=$B$3)*(Matches!$D$3:$D$502=B39)*(Matches!$O$3:$O$502="Completed"))+SUMPRODUCT((Matches!$B$3:$B$502=$B$3)*(Matches!$E$3:$E$502=B39)*(Matches!$O$3:$O$502="Completed"))),"—") | D39: =IFERROR(IF(B39="","",SUMPRODUCT((Matches!$B$3:$B$502=$B$3)*(Matches!$D$3:$D$502=B39)*(Matches!$N$3:$N$502=B39)*(Matches!$O$3:$O$502="Completed"))+SUMPRODUCT((Matches!$B$3:$B$502=$B$3)*(Matches!$E$3:$E$502=B39)*(Matches!$N$3:$N$502=B39)*(Matches!$O$3:$O$502="Completed"))),"—") | E39: =IFERROR(IF(B39="","",SUMPRODUCT((Matches!$B$3:$B$502=$B$3)*(Matches!$D$3:$D$502=B39)*(Matches!$N$3:$N$502="Draw")*(Matches!$O$3:$O$502="Completed"))+SUMPRODUCT((Matches!$B$3:$B$502=$B$3)*(Matches!$E$3:$E$502=B39)*(Matches!$N$3:$N$502="Draw")*(Matches!$O$3:$O$502="Completed"))),"—") | F39: =IFERROR(IF(B39="","",IF(ISNUMBER(C39),C39-D39-E39,"—")),"—") | G39: =IFERROR(IF(B39="","",IF(ISNUMBER(D39),D39*Setup!$B$8+E39*Setup!$B$9+F39*Setup!$B$10,"—")),"—") | H39: =IFERROR(IF(B39="","",SUMPRODUCT((Matches!$B$3:$B$502=$B$3)*(Matches!$D$3:$D$502=B39)*(Matches!$O$3:$O$502="Completed")*IF(ISNUMBER(Matches!$L$3:$L$502),Matches!$L$3:$L$502,0))+SUMPRODUCT((Matches!$B$3:$B$502=$B$3)*(Matches!$E$3:$E$502=B39)*(Matches!$O$3:$O$502="Completed")*IF(ISNUMBER(Matches!$M$3:$M$502),Matches!$M$3:$M$502,0))),"—") | I39: =IFERROR(IF(B39="","",SUMPRODUCT((Matches!$B$3:$B$502=$B$3)*(Matches!$D$3:$D$502=B39)*(Matches!$O$3:$O$502="Completed")*IF(ISNUMBER(Matches!$M$3:$M$502),Matches!$M$3:$M$502,0))+SUMPRODUCT((Matches!$B$3:$B$502=$B$3)*(Matches!$E$3:$E$502=B39)*(Matches!$O$3:$O$502="Completed")*IF(ISNUMBER(Matches!$L$3:$L$502),Matches!$L$3:$L$502,0))),"—") | J39: =IFERROR(IF(B39="","",IF(ISNUMBER(H39),H39-I39,"—")),"—")
B40: =IFERROR(INDEX(Teams!$B$3:$B$52,SMALL(IF(Teams!$A$3:$A$52="B",ROW(Teams!$A$3:$A$52)-ROW(Teams!$A$3)+1),9)),"") | C40: =IFERROR(IF(B40="","",SUMPRODUCT((Matches!$B$3:$B$502=$B$3)*(Matches!$D$3:$D$502=B40)*(Matches!$O$3:$O$502="Completed"))+SUMPRODUCT((Matches!$B$3:$B$502=$B$3)*(Matches!$E$3:$E$502=B40)*(Matches!$O$3:$O$502="Completed"))),"—") | D40: =IFERROR(IF(B40="","",SUMPRODUCT((Matches!$B$3:$B$502=$B$3)*(Matches!$D$3:$D$502=B40)*(Matches!$N$3:$N$502=B40)*(Matches!$O$3:$O$502="Completed"))+SUMPRODUCT((Matches!$B$3:$B$502=$B$3)*(Matches!$E$3:$E$502=B40)*(Matches!$N$3:$N$502=B40)*(Matches!$O$3:$O$502="Completed"))),"—") | E40: =IFERROR(IF(B40="","",SUMPRODUCT((Matches!$B$3:$B$502=$B$3)*(Matches!$D$3:$D$502=B40)*(Matches!$N$3:$N$502="Draw")*(Matches!$O$3:$O$502="Completed"))+SUMPRODUCT((Matches!$B$3:$B$502=$B$3)*(Matches!$E$3:$E$502=B40)*(Matches!$N$3:$N$502="Draw")*(Matches!$O$3:$O$502="Completed"))),"—") | F40: =IFERROR(IF(B40="","",IF(ISNUMBER(C40),C40-D40-E40,"—")),"—") | G40: =IFERROR(IF(B40="","",IF(ISNUMBER(D40),D40*Setup!$B$8+E40*Setup!$B$9+F40*Setup!$B$10,"—")),"—") | H40: =IFERROR(IF(B40="","",SUMPRODUCT((Matches!$B$3:$B$502=$B$3)*(Matches!$D$3:$D$502=B40)*(Matches!$O$3:$O$502="Completed")*IF(ISNUMBER(Matches!$L$3:$L$502),Matches!$L$3:$L$502,0))+SUMPRODUCT((Matches!$B$3:$B$502=$B$3)*(Matches!$E$3:$E$502=B40)*(Matches!$O$3:$O$502="Completed")*IF(ISNUMBER(Matches!$M$3:$M$502),Matches!$M$3:$M$502,0))),"—") | I40: =IFERROR(IF(B40="","",SUMPRODUCT((Matches!$B$3:$B$502=$B$3)*(Matches!$D$3:$D$502=B40)*(Matches!$O$3:$O$502="Completed")*IF(ISNUMBER(Matches!$M$3:$M$502),Matches!$M$3:$M$502,0))+SUMPRODUCT((Matches!$B$3:$B$502=$B$3)*(Matches!$E$3:$E$502=B40)*(Matches!$O$3:$O$502="Completed")*IF(ISNUMBER(Matches!$L$3:$L$502),Matches!$L$3:$L$502,0))),"—") | J40: =IFERROR(IF(B40="","",IF(ISNUMBER(H40),H40-I40,"—")),"—")
